Workbook

Sheet Dashboard
A1: 🏆 ATHLETE PERFORMANCE DASHBOARD
A2: ="Powerlifting · CrossFit · HYROX | " & AthleteName & " | Today: " & TEXT(TODAY(),"dddd, mmmm d, yyyy") -> Powerlifting · CrossFit · HYROX | Athlete | Today: Thursday, July 30, 2026
A3: =HYPERLINK("#'Daily Tracker'!A1","📅 Daily") -> 📅 Daily | C3: =HYPERLINK("#'Workout Log'!A1","🏋️ Workouts") -> 🏋️ Workouts | E3: =HYPERLINK("#'Cardio & HYROX Log'!A1","🏃 Cardio") -> 🏃 Cardio | G3: =HYPERLINK("#'Recovery Tracker'!A1","🛌 Recovery") -> 🛌 Recovery | I3: =HYPERLINK("#'Nutrition Tracker'!A1","🥗 Nutrition") -> 🥗 Nutrition | K3: =HYPERLINK("#'Weekly Dashboard'!A1","📊 Weekly") -> 📊 Weekly | M3: =HYPERLINK("#'Monthly Dashboard'!A1","🗓 Monthly") -> 🗓 Monthly | O3: =HYPERLINK("#'Personal Record (PR) Tracker'!A1","🏆 PRs") -> 🏆 PRs | Q3: =HYPERLINK("#'Goals & Settings'!A1","⚙️ Settings") -> ⚙️ Settings
A5: KEY PERFORMANCE INDICATORS
A6: TOTAL STEPS | F6: AVG DAILY STEPS | K6: AVG SLEEP | P6: WORKOUT SESSIONS
A7: =SUM('Daily Tracker'!E5:E369) -> 11500 | F7: =IFERROR(AVERAGE('Daily Tracker'!E5:E369),0) -> 11500 | K7: =IFERROR(AVERAGE('Daily Tracker'!F5:F369),0) -> 7.5 | P7: =SUM('Daily Tracker'!X5:X369) -> 1
A10: TRAINING HOURS | F10: CALORIES BURNED | K10: WATER INTAKE | P10: CURRENT WEIGHT
A11: =SUM('Daily Tracker'!M5:M369)/60 -> 1.25 | F11: =SUM('Daily Tracker'!K5:K369) -> 3100 | K11: =SUM('Daily Tracker'!I5:I369) -> 4.2 | P11: =IFERROR(LOOKUP(2,1/('Daily Tracker'!$G$5:$G$369<>""),'Daily Tracker'!$G$5:$G$369),StartWeight) -> 76
A14: WEIGHT CHANGE | F14: ACTIVITY STREAK | K14: WORKOUT COMPLIANCE % | P14: RECOVERY SCORE
A15: =IFERROR(LOOKUP(2,1/('Daily Tracker'!$G$5:$G$369<>""),'Daily Tracker'!$G$5:$G$369),StartWeight)-StartWeight -> 1 | F15: =IFERROR(INDEX('Daily Tracker'!$Y$5:$Y$369,MATCH(TODAY(),'Daily Tracker'!$A$5:$A$369,0)),0) -> 0 | K15: =IFERROR(SUM('Daily Tracker'!X5:X369)/(SessionsGoal/7*(TODAY()-StartDate+1)),0) -> 0.0066350711 | P15: =IFERROR(LOOKUP(2,1/('Recovery Tracker'!$E$5:$E$369<>""),'Recovery Tracker'!$E$5:$E$369),0) -> 84
P16: out of 100
A18: MONTHLY GOAL COMPLETION
A19: =IFERROR(AVERAGEIFS('Daily Tracker'!$AC$5:$AC$369,'Daily Tracker'!$D$5:$D$369,TEXT(TODAY(),"mmm")),0) -> 0
A20: Avg Athlete Score, this month
A22: STREAK TRACKER
A23: WORKOUT STREAK | F23: STEP GOAL STREAK | K23: SLEEP GOAL STREAK | P23: HYDRATION STREAK
A24: =IFERROR(INDEX('Daily Tracker'!$Y$5:$Y$369,MATCH(TODAY(),'Daily Tracker'!$A$5:$A$369,0)),0) -> 0 | F24: =IFERROR(INDEX('Daily Tracker'!$Z$5:$Z$369,MATCH(TODAY(),'Daily Tracker'!$A$5:$A$369,0)),0) -> 0 | K24: =IFERROR(INDEX('Daily Tracker'!$AA$5:$AA$369,MATCH(TODAY(),'Daily Tracker'!$A$5:$A$369,0)),0) -> 0 | P24: =IFERROR(INDEX('Daily Tracker'!$AB$5:$AB$369,MATCH(TODAY(),'Daily Tracker'!$A$5:$A$369,0)),0) -> 0
A25: days in a row | F25: days in a row | K25: days in a row | P25: days in a row
A27: ="🔥 Longest streak ever: " & MAX('Daily Tracker'!Y5:Y369) & " consecutive workout days" -> 🔥 Longest streak ever: 1 consecutive workout days
A29: ACHIEVEMENT BADGES
A30: First Workout | E30: 5-Workout Streak | I30: 10-Workout Streak | M30: 30-Workout Streak | Q30: 100,000 Steps Week
A31: =IF(SUM('Daily Tracker'!X5:X369)>=1,"✅ Unlocked","🔒 Locked") -> ✅ Unlocked | E31: =IF(MAX('Daily Tracker'!Y5:Y369)>=5,"✅ Unlocked","🔒 Locked") -> 🔒 Locked | I31: =IF(MAX('Daily Tracker'!Y5:Y369)>=10,"✅ Unlocked","🔒 Locked") -> 🔒 Locked | M31: =IF(MAX('Daily Tracker'!Y5:Y369)>=30,"✅ Unlocked","🔒 Locked") -> 🔒 Locked | Q31: =IF(MAX('Weekly Dashboard'!C5:C57)>=100000,"✅ Unlocked","🔒 Locked") -> 🔒 Locked
A34: Perfect Recovery Week | E34: Sleep Champion (7-day) | I34: Hydration Master (7-day) | M34: New PR (last 7 days) | Q34: Monthly Consistency Award
A35: =IF(MAX('Weekly Dashboard'!L5:L57)>=95,"✅ Unlocked","🔒 Locked") -> 🔒 Locked | E35: =IF(MAX('Daily Tracker'!AA5:AA369)>=7,"✅ Unlocked","🔒 Locked") -> 🔒 Locked | I35: =IF(MAX('Daily Tracker'!AB5:AB369)>=7,"✅ Unlocked","🔒 Locked") -> 🔒 Locked | M35: =IF(COUNTIFS('Workout Log'!$A$5:$A$504,">="&(TODAY()-7),'Workout Log'!$I$5:$I$504,"Yes")>0,"✅ Unlocked","🔒 Locked") -> 🔒 Locked | Q35: =IF(MAX('Monthly Dashboard'!N5:N16)>=0.9,"✅ Unlocked","🔒 Locked") -> 🔒 Locked
A40: TRENDS & ANALYTICS

Sheet Daily Tracker
A1: 📅 DAILY TRACKER
A2: Blue cells = enter your data. All other columns calculate automatically.
A4: Date | B4: Day | C4: Wk # | D4: Month | E4: Steps | F4: Sleep (hrs) | G4: Weight (kg) | H4: Body Fat % | I4: Water (L) | J4: Cal. In | K4: Cal. Burned | L4: Workout Type | M4: Duration (min) | N4: RPE | O4: Mood | P4: Energy | Q4: Recovery | R4: Stress | S4: Notes | T4: Step Goal % | U4: Sleep Goal % | V4: Water Goal % | W4: Daily Goal % | X4: WO Day | Y4: Workout Streak | Z4: Step Streak | AA4: Sleep Streak | AB4: Water Streak | AC4: Athlete Score | AE4: THIS WEEK / THIS MONTH — LIVE SNAPSHOT
A5: =StartDate -> 46023 | B5: =TEXT(A5,"ddd") -> Thu | C5: =INT((A5-StartDate)/7)+1 -> 1 | D5: =TEXT(A5,"mmm") -> Jan | E5: 11500 | F5: 7.5 | G5: 76 | H5: 17.8 | I5: 4.2 | J5: 2850 | K5: 3100 | L5: Powerlifting | M5: 75 | N5: 8 | O5: 4 | P5: 4 | Q5: 4 | R5: 2 | S5: Heavy squat day, felt strong. EXAMPLE ROW — overwrite with your own data (or delete the values). | T5: =IF(E5="","",E5/StepGoal) -> 1.15 | U5: =IF(F5="","",F5/SleepGoal) -> 0.9375 | V5: =IF(I5="","",I5/WaterGoal) -> 1.05 | W5: =IF(COUNT(E5,F5,I5)=0,"",(IF(N(T5)>=1,1,0)+IF(N(U5)>=1,1,0)+IF(N(V5)>=1,1,0))/3) -> 0.66666667 | X5: =IF(AND(L5<>"",L5<>"Rest Day"),1,0) -> 1 | Y5: =X5 -> 1 | Z5: =IF(N(T5)>=1,1,0) -> 1 | AA5: =IF(N(U5)>=1,1,0) -> 0 | AB5: =IF(N(V5)>=1,1,0) -> 1 | AC5: =IF(COUNT(E5,F5,I5,J5)=0,"",ROUND((MIN(IFERROR(E5/StepGoal,0),1)*100)*0.2+(MIN(IFERROR(F5/SleepGoal,0),1)*100)*0.2+(IF(L5="",0,IF(L5="Rest Day",100,MIN(IFERROR(M5/60,0),1)*100)))*0.25+(IFERROR(INDEX('Recovery Tracker'!$E$5:$E$369,MATCH(A5,'Recovery Tracker'!$A$5:$A$369,0))+0,70))*0.15+(MIN(IFERROR(I5/WaterGoal,0),1)*100)*0.1+(IF(J5="",0,MAX(0,100-MIN(ABS(J5-CalorieGoal)/CalorieGoal,1)*100)))*0.1,0)) -> 96
A6: =A5+1 -> 46024 | B6: =TEXT(A6,"ddd") -> Fri | C6: =INT((A6-StartDate)/7)+1 -> 1 | D6: =TEXT(A6,"mmm") -> Jan | T6: =IF(E6="","",E6/StepGoal) | U6: =IF(F6="","",F6/SleepGoal) | V6: =IF(I6="","",I6/WaterGoal) | W6: =IF(COUNT(E6,F6,I6)=0,"",(IF(N(T6)>=1,1,0)+IF(N(U6)>=1,1,0)+IF(N(V6)>=1,1,0))/3) | X6: =IF(AND(L6<>"",L6<>"Rest Day"),1,0) -> 0 | Y6: =IF(X6=1,Y5+1,0) -> 0 | Z6: =IF(N(T6)>=1,Z5+1,0) -> 0 | AA6: =IF(N(U6)>=1,AA5+1,0) -> 0 | AB6: =IF(N(V6)>=1,AB5+1,0) -> 0 | AC6: =IF(COUNT(E6,F6,I6,J6)=0,"",ROUND((MIN(IFERROR(E6/StepGoal,0),1)*100)*0.2+(MIN(IFERROR(F6/SleepGoal,0),1)*100)*0.2+(IF(L6="",0,IF(L6="Rest Day",100,MIN(IFERROR(M6/60,0),1)*100)))*0.25+(IFERROR(INDEX('Recovery Tracker'!$E$5:$E$369,MATCH(A6,'Recovery Tracker'!$A$5:$A$369,0))+0,70))*0.15+(MIN(IFERROR(I6/WaterGoal,0),1)*100)*0.1+(IF(J6="",0,MAX(0,100-MIN(ABS(J6-CalorieGoal)/CalorieGoal,1)*100)))*0.1,0)) | AE6: This Week — Total Steps | AG6: =SUMIFS($E$5:$E$369,$C$5:$C$369,INT((TODAY()-StartDate)/7)+1) -> 0
A7: =A6+1 -> 46025 | B7: =TEXT(A7,"ddd") -> Sat | C7: =INT((A7-StartDate)/7)+1 -> 1 | D7: =TEXT(A7,"mmm") -> Jan | T7: =IF(E7="","",E7/StepGoal) | U7: =IF(F7="","",F7/SleepGoal) | V7: =IF(I7="","",I7/WaterGoal) | W7: =IF(COUNT(E7,F7,I7)=0,"",(IF(N(T7)>=1,1,0)+IF(N(U7)>=1,1,0)+IF(N(V7)>=1,1,0))/3) | X7: =IF(AND(L7<>"",L7<>"Rest Day"),1,0) -> 0 | Y7: =IF(X7=1,Y6+1,0) -> 0 | Z7: =IF(N(T7)>=1,Z6+1,0) -> 0 | AA7: =IF(N(U7)>=1,AA6+1,0) -> 0 | AB7: =IF(N(V7)>=1,AB6+1,0) -> 0 | AC7: =IF(COUNT(E7,F7,I7,J7)=0,"",ROUND((MIN(IFERROR(E7/StepGoal,0),1)*100)*0.2+(MIN(IFERROR(F7/SleepGoal,0),1)*100)*0.2+(IF(L7="",0,IF(L7="Rest Day",100,MIN(IFERROR(M7/60,0),1)*100)))*0.25+(IFERROR(INDEX('Recovery Tracker'!$E$5:$E$369,MATCH(A7,'Recovery Tracker'!$A$5:$A$369,0))+0,70))*0.15+(MIN(IFERROR(I7/WaterGoal,0),1)*100)*0.1+(IF(J7="",0,MAX(0,100-MIN(ABS(J7-CalorieGoal)/CalorieGoal,1)*100)))*0.1,0)) | AE7: This Week — Avg Sleep | AG7: =IFERROR(AVERAGEIFS($F$5:$F$369,$C$5:$C$369,INT((TODAY()-StartDate)/7)+1),0) -> 0
A8: =A7+1 -> 46026 | B8: =TEXT(A8,"ddd") -> Sun | C8: =INT((A8-StartDate)/7)+1 -> 1 | D8: =TEXT(A8,"mmm") -> Jan | T8: =IF(E8="","",E8/StepGoal) | U8: =IF(F8="","",F8/SleepGoal) | V8: =IF(I8="","",I8/WaterGoal) | W8: =IF(COUNT(E8,F8,I8)=0,"",(IF(N(T8)>=1,1,0)+IF(N(U8)>=1,1,0)+IF(N(V8)>=1,1,0))/3) | X8: =IF(AND(L8<>"",L8<>"Rest Day"),1,0) -> 0 | Y8: =IF(X8=1,Y7+1,0) -> 0 | Z8: =IF(N(T8)>=1,Z7+1,0) -> 0 | AA8: =IF(N(U8)>=1,AA7+1,0) -> 0 | AB8: =IF(N(V8)>=1,AB7+1,0) -> 0 | AC8: =IF(COUNT(E8,F8,I8,J8)=0,"",ROUND((MIN(IFERROR(E8/StepGoal,0),1)*100)*0.2+(MIN(IFERROR(F8/SleepGoal,0),1)*100)*0.2+(IF(L8="",0,IF(L8="Rest Day",100,MIN(IFERROR(M8/60,0),1)*100)))*0.25+(IFERROR(INDEX('Recovery Tracker'!$E$5:$E$369,MATCH(A8,'Recovery Tracker'!$A$5:$A$369,0))+0,70))*0.15+(MIN(IFERROR(I8/WaterGoal,0),1)*100)*0.1+(IF(J8="",0,MAX(0,100-MIN(ABS(J8-CalorieGoal)/CalorieGoal,1)*100)))*0.1,0)) | AE8: This Week — Workouts | AG8: =COUNTIFS($C$5:$C$369,INT((TODAY()-StartDate)/7)+1,$X$5:$X$369,1) -> 0
A9: =A8+1 -> 46027 | B9: =TEXT(A9,"ddd") -> Mon | C9: =INT((A9-StartDate)/7)+1 -> 1 | D9: =TEXT(A9,"mmm") -> Jan | T9: =IF(E9="","",E9/StepGoal) | U9: =IF(F9="","",F9/SleepGoal) | V9: =IF(I9="","",I9/WaterGoal) | W9: =IF(COUNT(E9,F9,I9)=0,"",(IF(N(T9)>=1,1,0)+IF(N(U9)>=1,1,0)+IF(N(V9)>=1,1,0))/3) | X9: =IF(AND(L9<>"",L9<>"Rest Day"),1,0) -> 0 | Y9: =IF(X9=1,Y8+1,0) -> 0 | Z9: =IF(N(T9)>=1,Z8+1,0) -> 0 | AA9: =IF(N(U9)>=1,AA8+1,0) -> 0 | AB9: =IF(N(V9)>=1,AB8+1,0) -> 0 | AC9: =IF(COUNT(E9,F9,I9,J9)=0,"",ROUND((MIN(IFERROR(E9/StepGoal,0),1)*100)*0.2+(MIN(IFERROR(F9/SleepGoal,0),1)*100)*0.2+(IF(L9="",0,IF(L9="Rest Day",100,MIN(IFERROR(M9/60,0),1)*100)))*0.25+(IFERROR(INDEX('Recovery Tracker'!$E$5:$E$369,MATCH(A9,'Recovery Tracker'!$A$5:$A$369,0))+0,70))*0.15+(MIN(IFERROR(I9/WaterGoal,0),1)*100)*0.1+(IF(J9="",0,MAX(0,100-MIN(ABS(J9-CalorieGoal)/CalorieGoal,1)*100)))*0.1,0)) | AE9: This Week — Total Water (L) | AG9: =SUMIFS($I$5:$I$369,$C$5:$C$369,INT((TODAY()-StartDate)/7)+1) -> 0
A10: =A9+1 -> 46028 | B10: =TEXT(A10,"ddd") -> Tue | C10: =INT((A10-StartDate)/7)+1 -> 1 | D10: =TEXT(A10,"mmm") -> Jan | T10: =IF(E10="","",E10/StepGoal) | U10: =IF(F10="","",F10/SleepGoal) | V10: =IF(I10="","",I10/WaterGoal) | W10: =IF(COUNT(E10,F10,I10)=0,"",(IF(N(T10)>=1,1,0)+IF(N(U10)>=1,1,0)+IF(N(V10)>=1,1,0))/3) | X10: =IF(AND(L10<>"",L10<>"Rest Day"),1,0) -> 0 | Y10: =IF(X10=1,Y9+1,0) -> 0 | Z10: =IF(N(T10)>=1,Z9+1,0) -> 0 | AA10: =IF(N(U10)>=1,AA9+1,0) -> 0 | AB10: =IF(N(V10)>=1,AB9+1,0) -> 0 | AC10: =IF(COUNT(E10,F10,I10,J10)=0,"",ROUND((MIN(IFERROR(E10/StepGoal,0),1)*100)*0.2+(MIN(IFERROR(F10/SleepGoal,0),1)*100)*0.2+(IF(L10="",0,IF(L10="Rest Day",100,MIN(IFERROR(M10/60,0),1)*100)))*0.25+(IFERROR(INDEX('Recovery Tracker'!$E$5:$E$369,MATCH(A10,'Recovery Tracker'!$A$5:$A$369,0))+0,70))*0.15+(MIN(IFERROR(I10/WaterGoal,0),1)*100)*0.1+(IF(J10="",0,MAX(0,100-MIN(ABS(J10-CalorieGoal)/CalorieGoal,1)*100)))*0.1,0)) | AE10: This Month — Total Steps | AG10: =SUMIFS($E$5:$E$369,$D$5:$D$369,TEXT(TODAY(),"mmm")) -> 0
A11: =A10+1 -> 46029 | B11: =TEXT(A11,"ddd") -> Wed | C11: =INT((A11-StartDate)/7)+1 -> 1 | D11: =TEXT(A11,"mmm") -> Jan | T11: =IF(E11="","",E11/StepGoal) | U11: =IF(F11="","",F11/SleepGoal) | V11: =IF(I11="","",I11/WaterGoal) | W11: =IF(COUNT(E11,F11,I11)=0,"",(IF(N(T11)>=1,1,0)+IF(N(U11)>=1,1,0)+IF(N(V11)>=1,1,0))/3) | X11: =IF(AND(L11<>"",L11<>"Rest Day"),1,0) -> 0 | Y11: =IF(X11=1,Y10+1,0) -> 0 | Z11: =IF(N(T11)>=1,Z10+1,0) -> 0 | AA11: =IF(N(U11)>=1,AA10+1,0) -> 0 | AB11: =IF(N(V11)>=1,AB10+1,0) -> 0 | AC11: =IF(COUNT(E11,F11,I11,J11)=0,"",ROUND((MIN(IFERROR(E11/StepGoal,0),1)*100)*0.2+(MIN(IFERROR(F11/SleepGoal,0),1)*100)*0.2+(IF(L11="",0,IF(L11="Rest Day",100,MIN(IFERROR(M11/60,0),1)*100)))*0.25+(IFERROR(INDEX('Recovery Tracker'!$E$5:$E$369,MATCH(A11,'Recovery Tracker'!$A$5:$A$369,0))+0,70))*0.15+(MIN(IFERROR(I11/WaterGoal,0),1)*100)*0.1+(IF(J11="",0,MAX(0,100-MIN(ABS(J11-CalorieGoal)/CalorieGoal,1)*100)))*0.1,0)) | AE11: This Month — Avg Sleep | AG11: =IFERROR(AVERAGEIFS($F$5:$F$369,$D$5:$D$369,TEXT(TODAY(),"mmm")),0) -> 0
A12: =A11+1 -> 46030 | B12: =TEXT(A12,"ddd") -> Thu | C12: =INT((A12-StartDate)/7)+1 -> 2 | D12: =TEXT(A12,"mmm") -> Jan | T12: =IF(E12="","",E12/StepGoal) | U12: =IF(F12="","",F12/SleepGoal) | V12: =IF(I12="","",I12/WaterGoal) | W12: =IF(COUNT(E12,F12,I12)=0,"",(IF(N(T12)>=1,1,0)+IF(N(U12)>=1,1,0)+IF(N(V12)>=1,1,0))/3) | X12: =IF(AND(L12<>"",L12<>"Rest Day"),1,0) -> 0 | Y12: =IF(X12=1,Y11+1,0) -> 0 | Z12: =IF(N(T12)>=1,Z11+1,0) -> 0 | AA12: =IF(N(U12)>=1,AA11+1,0) -> 0 | AB12: =IF(N(V12)>=1,AB11+1,0) -> 0 | AC12: =IF(COUNT(E12,F12,I12,J12)=0,"",ROUND((MIN(IFERROR(E12/StepGoal,0),1)*100)*0.2+(MIN(IFERROR(F12/SleepGoal,0),1)*100)*0.2+(IF(L12="",0,IF(L12="Rest Day",100,MIN(IFERROR(M12/60,0),1)*100)))*0.25+(IFERROR(INDEX('Recovery Tracker'!$E$5:$E$369,MATCH(A12,'Recovery Tracker'!$A$5:$A$369,0))+0,70))*0.15+(MIN(IFERROR(I12/WaterGoal,0),1)*100)*0.1+(IF(J12="",0,MAX(0,100-MIN(ABS(J12-CalorieGoal)/CalorieGoal,1)*100)))*0.1,0)) | AE12: This Month — Workouts | AG12: =COUNTIFS($D$5:$D$369,TEXT(TODAY(),"mmm"),$X$5:$X$369,1) -> 0
A13: =A12+1 -> 46031 | B13: =TEXT(A13,"ddd") -> Fri | C13: =INT((A13-StartDate)/7)+1 -> 2 | D13: =TEXT(A13,"mmm") -> Jan | T13: =IF(E13="","",E13/StepGoal) | U13: =IF(F13="","",F13/SleepGoal) | V13: =IF(I13="","",I13/WaterGoal) | W13: =IF(COUNT(E13,F13,I13)=0,"",(IF(N(T13)>=1,1,0)+IF(N(U13)>=1,1,0)+IF(N(V13)>=1,1,0))/3) | X13: =IF(AND(L13<>"",L13<>"Rest Day"),1,0) -> 0 | Y13: =IF(X13=1,Y12+1,0) -> 0 | Z13: =IF(N(T13)>=1,Z12+1,0) -> 0 | AA13: =IF(N(U13)>=1,AA12+1,0) -> 0 | AB13: =IF(N(V13)>=1,AB12+1,0) -> 0 | AC13: =IF(COUNT(E13,F13,I13,J13)=0,"",ROUND((MIN(IFERROR(E13/StepGoal,0),1)*100)*0.2+(MIN(IFERROR(F13/SleepGoal,0),1)*100)*0.2+(IF(L13="",0,IF(L13="Rest Day",100,MIN(IFERROR(M13/60,0),1)*100)))*0.25+(IFERROR(INDEX('Recovery Tracker'!$E$5:$E$369,MATCH(A13,'Recovery Tracker'!$A$5:$A$369,0))+0,70))*0.15+(MIN(IFERROR(I13/WaterGoal,0),1)*100)*0.1+(IF(J13="",0,MAX(0,100-MIN(ABS(J13-CalorieGoal)/CalorieGoal,1)*100)))*0.1,0)) | AE13: Current Workout Streak | AG13: =IFERROR(INDEX($Y$5:$Y$369,MATCH(TODAY(),$A$5:$A$369,0)),0) -> 0
A14: =A13+1 -> 46032 | B14: =TEXT(A14,"ddd") -> Sat | C14: =INT((A14-StartDate)/7)+1 -> 2 | D14: =TEXT(A14,"mmm") -> Jan | T14: =IF(E14="","",E14/StepGoal) | U14: =IF(F14="","",F14/SleepGoal) | V14: =IF(I14="","",I14/WaterGoal) | W14: =IF(COUNT(E14,F14,I14)=0,"",(IF(N(T14)>=1,1,0)+IF(N(U14)>=1,1,0)+IF(N(V14)>=1,1,0))/3) | X14: =IF(AND(L14<>"",L14<>"Rest Day"),1,0) -> 0 | Y14: =IF(X14=1,Y13+1,0) -> 0 | Z14: =IF(N(T14)>=1,Z13+1,0) -> 0 | AA14: =IF(N(U14)>=1,AA13+1,0) -> 0 | AB14: =IF(N(V14)>=1,AB13+1,0) -> 0 | AC14: =IF(COUNT(E14,F14,I14,J14)=0,"",ROUND((MIN(IFERROR(E14/StepGoal,0),1)*100)*0.2+(MIN(IFERROR(F14/SleepGoal,0),1)*100)*0.2+(IF(L14="",0,IF(L14="Rest Day",100,MIN(IFERROR(M14/60,0),1)*100)))*0.25+(IFERROR(INDEX('Recovery Tracker'!$E$5:$E$369,MATCH(A14,'Recovery Tracker'!$A$5:$A$369,0))+0,70))*0.15+(MIN(IFERROR(I14/WaterGoal,0),1)*100)*0.1+(IF(J14="",0,MAX(0,100-MIN(ABS(J14-CalorieGoal)/CalorieGoal,1)*100)))*0.1,0)) | AE14: Longest Workout Streak | AG14: =MAX($Y$5:$Y$369) -> 1
A15: =A14+1 -> 46033 | B15: =TEXT(A15,"ddd") -> Sun | C15: =INT((A15-StartDate)/7)+1 -> 2 | D15: =TEXT(A15,"mmm") -> Jan | T15: =IF(E15="","",E15/StepGoal) | U15: =IF(F15="","",F15/SleepGoal) | V15: =IF(I15="","",I15/WaterGoal) | W15: =IF(COUNT(E15,F15,I15)=0,"",(IF(N(T15)>=1,1,0)+IF(N(U15)>=1,1,0)+IF(N(V15)>=1,1,0))/3) | X15: =IF(AND(L15<>"",L15<>"Rest Day"),1,0) -> 0 | Y15: =IF(X15=1,Y14+1,0) -> 0 | Z15: =IF(N(T15)>=1,Z14+1,0) -> 0 | AA15: =IF(N(U15)>=1,AA14+1,0) -> 0 | AB15: =IF(N(V15)>=1,AB14+1,0) -> 0 | AC15: =IF(COUNT(E15,F15,I15,J15)=0,"",ROUND((MIN(IFERROR(E15/StepGoal,0),1)*100)*0.2+(MIN(IFERROR(F15/SleepGoal,0),1)*100)*0.2+(IF(L15="",0,IF(L15="Rest Day",100,MIN(IFERROR(M15/60,0),1)*100)))*0.25+(IFERROR(INDEX('Recovery Tracker'!$E$5:$E$369,MATCH(A15,'Recovery Tracker'!$A$5:$A$369,0))+0,70))*0.15+(MIN(IFERROR(I15/WaterGoal,0),1)*100)*0.1+(IF(J15="",0,MAX(0,100-MIN(ABS(J15-CalorieGoal)/CalorieGoal,1)*100)))*0.1,0))
A16: =A15+1 -> 46034 | B16: =TEXT(A16,"ddd") -> Mon | C16: =INT((A16-StartDate)/7)+1 -> 2 | D16: =TEXT(A16,"mmm") -> Jan | T16: =IF(E16="","",E16/StepGoal) | U16: =IF(F16="","",F16/SleepGoal) | V16: =IF(I16="","",I16/WaterGoal) | W16: =IF(COUNT(E16,F16,I16)=0,"",(IF(N(T16)>=1,1,0)+IF(N(U16)>=1,1,0)+IF(N(V16)>=1,1,0))/3) | X16: =IF(AND(L16<>"",L16<>"Rest Day"),1,0) -> 0 | Y16: =IF(X16=1,Y15+1,0) -> 0 | Z16: =IF(N(T16)>=1,Z15+1,0) -> 0 | AA16: =IF(N(U16)>=1,AA15+1,0) -> 0 | AB16: =IF(N(V16)>=1,AB15+1,0) -> 0 | AC16: =IF(COUNT(E16,F16,I16,J16)=0,"",ROUND((MIN(IFERROR(E16/StepGoal,0),1)*100)*0.2+(MIN(IFERROR(F16/SleepGoal,0),1)*100)*0.2+(IF(L16="",0,IF(L16="Rest Day",100,MIN(IFERROR(M16/60,0),1)*100)))*0.25+(IFERROR(INDEX('Recovery Tracker'!$E$5:$E$369,MATCH(A16,'Recovery Tracker'!$A$5:$A$369,0))+0,70))*0.15+(MIN(IFERROR(I16/WaterGoal,0),1)*100)*0.1+(IF(J16="",0,MAX(0,100-MIN(ABS(J16-CalorieGoal)/CalorieGoal,1)*100)))*0.1,0))
A17: =A16+1 -> 46035 | B17: =TEXT(A17,"ddd") -> Tue | C17: =INT((A17-StartDate)/7)+1 -> 2 | D17: =TEXT(A17,"mmm") -> Jan | T17: =IF(E17="","",E17/StepGoal) | U17: =IF(F17="","",F17/SleepGoal) | V17: =IF(I17="","",I17/WaterGoal) | W17: =IF(COUNT(E17,F17,I17)=0,"",(IF(N(T17)>=1,1,0)+IF(N(U17)>=1,1,0)+IF(N(V17)>=1,1,0))/3) | X17: =IF(AND(L17<>"",L17<>"Rest Day"),1,0) -> 0 | Y17: =IF(X17=1,Y16+1,0) -> 0 | Z17: =IF(N(T17)>=1,Z16+1,0) -> 0 | AA17: =IF(N(U17)>=1,AA16+1,0) -> 0 | AB17: =IF(N(V17)>=1,AB16+1,0) -> 0 | AC17: =IF(COUNT(E17,F17,I17,J17)=0,"",ROUND((MIN(IFERROR(E17/StepGoal,0),1)*100)*0.2+(MIN(IFERROR(F17/SleepGoal,0),1)*100)*0.2+(IF(L17="",0,IF(L17="Rest Day",100,MIN(IFERROR(M17/60,0),1)*100)))*0.25+(IFERROR(INDEX('Recovery Tracker'!$E$5:$E$369,MATCH(A17,'Recovery Tracker'!$A$5:$A$369,0))+0,70))*0.15+(MIN(IFERROR(I17/WaterGoal,0),1)*100)*0.1+(IF(J17="",0,MAX(0,100-MIN(ABS(J17-CalorieGoal)/CalorieGoal,1)*100)))*0.1,0))
A18: =A17+1 -> 46036 | B18: =TEXT(A18,"ddd") -> Wed | C18: =INT((A18-StartDate)/7)+1 -> 2 | D18: =TEXT(A18,"mmm") -> Jan | T18: =IF(E18="","",E18/StepGoal) | U18: =IF(F18="","",F18/SleepGoal) | V18: =IF(I18="","",I18/WaterGoal) | W18: =IF(COUNT(E18,F18,I18)=0,"",(IF(N(T18)>=1,1,0)+IF(N(U18)>=1,1,0)+IF(N(V18)>=1,1,0))/3) | X18: =IF(AND(L18<>"",L18<>"Rest Day"),1,0) -> 0 | Y18: =IF(X18=1,Y17+1,0) -> 0 | Z18: =IF(N(T18)>=1,Z17+1,0) -> 0 | AA18: =IF(N(U18)>=1,AA17+1,0) -> 0 | AB18: =IF(N(V18)>=1,AB17+1,0) -> 0 | AC18: =IF(COUNT(E18,F18,I18,J18)=0,"",ROUND((MIN(IFERROR(E18/StepGoal,0),1)*100)*0.2+(MIN(IFERROR(F18/SleepGoal,0),1)*100)*0.2+(IF(L18="",0,IF(L18="Rest Day",100,MIN(IFERROR(M18/60,0),1)*100)))*0.25+(IFERROR(INDEX('Recovery Tracker'!$E$5:$E$369,MATCH(A18,'Recovery Tracker'!$A$5:$A$369,0))+0,70))*0.15+(MIN(IFERROR(I18/WaterGoal,0),1)*100)*0.1+(IF(J18="",0,MAX(0,100-MIN(ABS(J18-CalorieGoal)/CalorieGoal,1)*100)))*0.1,0))
A19: =A18+1 -> 46037 | B19: =TEXT(A19,"ddd") -> Thu | C19: =INT((A19-StartDate)/7)+1 -> 3 | D19: =TEXT(A19,"mmm") -> Jan | T19: =IF(E19="","",E19/StepGoal) | U19: =IF(F19="","",F19/SleepGoal) | V19: =IF(I19="","",I19/WaterGoal) | W19: =IF(COUNT(E19,F19,I19)=0,"",(IF(N(T19)>=1,1,0)+IF(N(U19)>=1,1,0)+IF(N(V19)>=1,1,0))/3) | X19: =IF(AND(L19<>"",L19<>"Rest Day"),1,0) -> 0 | Y19: =IF(X19=1,Y18+1,0) -> 0 | Z19: =IF(N(T19)>=1,Z18+1,0) -> 0 | AA19: =IF(N(U19)>=1,AA18+1,0) -> 0 | AB19: =IF(N(V19)>=1,AB18+1,0) -> 0 | AC19: =IF(COUNT(E19,F19,I19,J19)=0,"",ROUND((MIN(IFERROR(E19/StepGoal,0),1)*100)*0.2+(MIN(IFERROR(F19/SleepGoal,0),1)*100)*0.2+(IF(L19="",0,IF(L19="Rest Day",100,MIN(IFERROR(M19/60,0),1)*100)))*0.25+(IFERROR(INDEX('Recovery Tracker'!$E$5:$E$369,MATCH(A19,'Recovery Tracker'!$A$5:$A$369,0))+0,70))*0.15+(MIN(IFERROR(I19/WaterGoal,0),1)*100)*0.1+(IF(J19="",0,MAX(0,100-MIN(ABS(J19-CalorieGoal)/CalorieGoal,1)*100)))*0.1,0))
A20: =A19+1 -> 46038 | B20: =TEXT(A20,"ddd") -> Fri | C20: =INT((A20-StartDate)/7)+1 -> 3 | D20: =TEXT(A20,"mmm") -> Jan | T20: =IF(E20="","",E20/StepGoal) | U20: =IF(F20="","",F20/SleepGoal) | V20: =IF(I20="","",I20/WaterGoal) | W20: =IF(COUNT(E20,F20,I20)=0,"",(IF(N(T20)>=1,1,0)+IF(N(U20)>=1,1,0)+IF(N(V20)>=1,1,0))/3) | X20: =IF(AND(L20<>"",L20<>"Rest Day"),1,0) -> 0 | Y20: =IF(X20=1,Y19+1,0) -> 0 | Z20: =IF(N(T20)>=1,Z19+1,0) -> 0 | AA20: =IF(N(U20)>=1,AA19+1,0) -> 0 | AB20: =IF(N(V20)>=1,AB19+1,0) -> 0 | AC20: =IF(COUNT(E20,F20,I20,J20)=0,"",ROUND((MIN(IFERROR(E20/StepGoal,0),1)*100)*0.2+(MIN(IFERROR(F20/SleepGoal,0),1)*100)*0.2+(IF(L20="",0,IF(L20="Rest Day",100,MIN(IFERROR(M20/60,0),1)*100)))*0.25+(IFERROR(INDEX('Recovery Tracker'!$E$5:$E$369,MATCH(A20,'Recovery Tracker'!$A$5:$A$369,0))+0,70))*0.15+(MIN(IFERROR(I20/WaterGoal,0),1)*100)*0.1+(IF(J20="",0,MAX(0,100-MIN(ABS(J20-CalorieGoal)/CalorieGoal,1)*100)))*0.1,0))
A21: =A20+1 -> 46039 | B21: =TEXT(A21,"ddd") -> Sat | C21: =INT((A21-StartDate)/7)+1 -> 3 | D21: =TEXT(A21,"mmm") -> Jan | T21: =IF(E21="","",E21/StepGoal) | U21: =IF(F21="","",F21/SleepGoal) | V21: =IF(I21="","",I21/WaterGoal) | W21: =IF(COUNT(E21,F21,I21)=0,"",(IF(N(T21)>=1,1,0)+IF(N(U21)>=1,1,0)+IF(N(V21)>=1,1,0))/3) | X21: =IF(AND(L21<>"",L21<>"Rest Day"),1,0) -> 0 | Y21: =IF(X21=1,Y20+1,0) -> 0 | Z21: =IF(N(T21)>=1,Z20+1,0) -> 0 | AA21: =IF(N(U21)>=1,AA20+1,0) -> 0 | AB21: =IF(N(V21)>=1,AB20+1,0) -> 0 | AC21: =IF(COUNT(E21,F21,I21,J21)=0,"",ROUND((MIN(IFERROR(E21/StepGoal,0),1)*100)*0.2+(MIN(IFERROR(F21/SleepGoal,0),1)*100)*0.2+(IF(L21="",0,IF(L21="Rest Day",100,MIN(IFERROR(M21/60,0),1)*100)))*0.25+(IFERROR(INDEX('Recovery Tracker'!$E$5:$E$369,MATCH(A21,'Recovery Tracker'!$A$5:$A$369,0))+0,70))*0.15+(MIN(IFERROR(I21/WaterGoal,0),1)*100)*0.1+(IF(J21="",0,MAX(0,100-MIN(ABS(J21-CalorieGoal)/CalorieGoal,1)*100)))*0.1,0))
A22: =A21+1 -> 46040 | B22: =TEXT(A22,"ddd") -> Sun | C22: =INT((A22-StartDate)/7)+1 -> 3 | D22: =TEXT(A22,"mmm") -> Jan | T22: =IF(E22="","",E22/StepGoal) | U22: =IF(F22="","",F22/SleepGoal) | V22: =IF(I22="","",I22/WaterGoal) | W22: =IF(COUNT(E22,F22,I22)=0,"",(IF(N(T22)>=1,1,0)+IF(N(U22)>=1,1,0)+IF(N(V22)>=1,1,0))/3) | X22: =IF(AND(L22<>"",L22<>"Rest Day"),1,0) -> 0 | Y22: =IF(X22=1,Y21+1,0) -> 0 | Z22: =IF(N(T22)>=1,Z21+1,0) -> 0 | AA22: =IF(N(U22)>=1,AA21+1,0) -> 0 | AB22: =IF(N(V22)>=1,AB21+1,0) -> 0 | AC22: =IF(COUNT(E22,F22,I22,J22)=0,"",ROUND((MIN(IFERROR(E22/StepGoal,0),1)*100)*0.2+(MIN(IFERROR(F22/SleepGoal,0),1)*100)*0.2+(IF(L22="",0,IF(L22="Rest Day",100,MIN(IFERROR(M22/60,0),1)*100)))*0.25+(IFERROR(INDEX('Recovery Tracker'!$E$5:$E$369,MATCH(A22,'Recovery Tracker'!$A$5:$A$369,0))+0,70))*0.15+(MIN(IFERROR(I22/WaterGoal,0),1)*100)*0.1+(IF(J22="",0,MAX(0,100-MIN(ABS(J22-CalorieGoal)/CalorieGoal,1)*100)))*0.1,0))
A23: =A22+1 -> 46041 | B23: =TEXT(A23,"ddd") -> Mon | C23: =INT((A23-StartDate)/7)+1 -> 3 | D23: =TEXT(A23,"mmm") -> Jan | T23: =IF(E23="","",E23/StepGoal) | U23: =IF(F23="","",F23/SleepGoal) | V23: =IF(I23="","",I23/WaterGoal) | W23: =IF(COUNT(E23,F23,I23)=0,"",(IF(N(T23)>=1,1,0)+IF(N(U23)>=1,1,0)+IF(N(V23)>=1,1,0))/3) | X23: =IF(AND(L23<>"",L23<>"Rest Day"),1,0) -> 0 | Y23: =IF(X23=1,Y22+1,0) -> 0 | Z23: =IF(N(T23)>=1,Z22+1,0) -> 0 | AA23: =IF(N(U23)>=1,AA22+1,0) -> 0 | AB23: =IF(N(V23)>=1,AB22+1,0) -> 0 | AC23: =IF(COUNT(E23,F23,I23,J23)=0,"",ROUND((MIN(IFERROR(E23/StepGoal,0),1)*100)*0.2+(MIN(IFERROR(F23/SleepGoal,0),1)*100)*0.2+(IF(L23="",0,IF(L23="Rest Day",100,MIN(IFERROR(M23/60,0),1)*100)))*0.25+(IFERROR(INDEX('Recovery Tracker'!$E$5:$E$369,MATCH(A23,'Recovery Tracker'!$A$5:$A$369,0))+0,70))*0.15+(MIN(IFERROR(I23/WaterGoal,0),1)*100)*0.1+(IF(J23="",0,MAX(0,100-MIN(ABS(J23-CalorieGoal)/CalorieGoal,1)*100)))*0.1,0))
A24: =A23+1 -> 46042 | B24: =TEXT(A24,"ddd") -> Tue | C24: =INT((A24-StartDate)/7)+1 -> 3 | D24: =TEXT(A24,"mmm") -> Jan | T24: =IF(E24="","",E24/StepGoal) | U24: =IF(F24="","",F24/SleepGoal) | V24: =IF(I24="","",I24/WaterGoal) | W24: =IF(COUNT(E24,F24,I24)=0,"",(IF(N(T24)>=1,1,0)+IF(N(U24)>=1,1,0)+IF(N(V24)>=1,1,0))/3) | X24: =IF(AND(L24<>"",L24<>"Rest Day"),1,0) -> 0 | Y24: =IF(X24=1,Y23+1,0) -> 0 | Z24: =IF(N(T24)>=1,Z23+1,0) -> 0 | AA24: =IF(N(U24)>=1,AA23+1,0) -> 0 | AB24: =IF(N(V24)>=1,AB23+1,0) -> 0 | AC24: =IF(COUNT(E24,F24,I24,J24)=0,"",ROUND((MIN(IFERROR(E24/StepGoal,0),1)*100)*0.2+(MIN(IFERROR(F24/SleepGoal,0),1)*100)*0.2+(IF(L24="",0,IF(L24="Rest Day",100,MIN(IFERROR(M24/60,0),1)*100)))*0.25+(IFERROR(INDEX('Recovery Tracker'!$E$5:$E$369,MATCH(A24,'Recovery Tracker'!$A$5:$A$369,0))+0,70))*0.15+(MIN(IFERROR(I24/WaterGoal,0),1)*100)*0.1+(IF(J24="",0,MAX(0,100-MIN(ABS(J24-CalorieGoal)/CalorieGoal,1)*100)))*0.1,0))
A25: =A24+1 -> 46043 | B25: =TEXT(A25,"ddd") -> Wed | C25: =INT((A25-StartDate)/7)+1 -> 3 | D25: =TEXT(A25,"mmm") -> Jan | T25: =IF(E25="","",E25/StepGoal) | U25: =IF(F25="","",F25/SleepGoal) | V25: =IF(I25="","",I25/WaterGoal) | W25: =IF(COUNT(E25,F25,I25)=0,"",(IF(N(T25)>=1,1,0)+IF(N(U25)>=1,1,0)+IF(N(V25)>=1,1,0))/3) | X25: =IF(AND(L25<>"",L25<>"Rest Day"),1,0) -> 0 | Y25: =IF(X25=1,Y24+1,0) -> 0 | Z25: =IF(N(T25)>=1,Z24+1,0) -> 0 | AA25: =IF(N(U25)>=1,AA24+1,0) -> 0 | AB25: =IF(N(V25)>=1,AB24+1,0) -> 0 | AC25: =IF(COUNT(E25,F25,I25,J25)=0,"",ROUND((MIN(IFERROR(E25/StepGoal,0),1)*100)*0.2+(MIN(IFERROR(F25/SleepGoal,0),1)*100)*0.2+(IF(L25="",0,IF(L25="Rest Day",100,MIN(IFERROR(M25/60,0),1)*100)))*0.25+(IFERROR(INDEX('Recovery Tracker'!$E$5:$E$369,MATCH(A25,'Recovery Tracker'!$A$5:$A$369,0))+0,70))*0.15+(MIN(IFERROR(I25/WaterGoal,0),1)*100)*0.1+(IF(J25="",0,MAX(0,100-MIN(ABS(J25-CalorieGoal)/CalorieGoal,1)*100)))*0.1,0))
A26: =A25+1 -> 46044 | B26: =TEXT(A26,"ddd") -> Thu | C26: =INT((A26-StartDate)/7)+1 -> 4 | D26: =TEXT(A26,"mmm") -> Jan | T26: =IF(E26="","",E26/StepGoal) | U26: =IF(F26="","",F26/SleepGoal) | V26: =IF(I26="","",I26/WaterGoal) | W26: =IF(COUNT(E26,F26,I26)=0,"",(IF(N(T26)>=1,1,0)+IF(N(U26)>=1,1,0)+IF(N(V26)>=1,1,0))/3) | X26: =IF(AND(L26<>"",L26<>"Rest Day"),1,0) -> 0 | Y26: =IF(X26=1,Y25+1,0) -> 0 | Z26: =IF(N(T26)>=1,Z25+1,0) -> 0 | AA26: =IF(N(U26)>=1,AA25+1,0) -> 0 | AB26: =IF(N(V26)>=1,AB25+1,0) -> 0 | AC26: =IF(COUNT(E26,F26,I26,J26)=0,"",ROUND((MIN(IFERROR(E26/StepGoal,0),1)*100)*0.2+(MIN(IFERROR(F26/SleepGoal,0),1)*100)*0.2+(IF(L26="",0,IF(L26="Rest Day",100,MIN(IFERROR(M26/60,0),1)*100)))*0.25+(IFERROR(INDEX('Recovery Tracker'!$E$5:$E$369,MATCH(A26,'Recovery Tracker'!$A$5:$A$369,0))+0,70))*0.15+(MIN(IFERROR(I26/WaterGoal,0),1)*100)*0.1+(IF(J26="",0,MAX(0,100-MIN(ABS(J26-CalorieGoal)/CalorieGoal,1)*100)))*0.1,0))
... A369: =A368+1 -> 46387 | B369: =TEXT(A369,"ddd") -> Thu | C369: =INT((A369-StartDate)/7)+1 -> 53 | D369: =TEXT(A369,"mmm") -> Dec | T369: =IF(E369="","",E369/StepGoal) | U369: =IF(F369="","",F369/SleepGoal) | V369: =IF(I369="","",I369/WaterGoal) | W369: =IF(COUNT(E369,F369,I369)=0,"",(IF(N(T369)>=1,1,0)+IF(N(U369)>=1,1,0)+IF(N(V369)>=1,1,0))/3) | X369: =IF(AND(L369<>"",L369<>"Rest Day"),1,0) -> 0 | Y369: =IF(X369=1,Y368+1,0) -> 0 | Z369: =IF(N(T369)>=1,Z368+1,0) -> 0 | AA369: =IF(N(U369)>=1,AA368+1,0) -> 0 | AB369: =IF(N(V369)>=1,AB368+1,0) -> 0 | AC369: =IF(COUNT(E369,F369,I369,J369)=0,"",ROUND((MIN(IFERROR(E369/StepGoal,0),1)*100)*0.2+(MIN(IFERROR(F369/SleepGoal,0),1)*100)*0.2+(IF(L369="",0,IF(L369="Rest Day",100,MIN(IFERROR(M369/60,0),1)*100)))*0.25+(IFERROR(INDEX('Recovery Tracker'!$E$5:$E$369,MATCH(A369,'Recovery Tracker'!$A$5:$A$369,0))+0,70))*0.15+(MIN(IFERROR(I369/WaterGoal,0),1)*100)*0.1+(IF(J369="",0,MAX(0,100-MIN(ABS(J369-CalorieGoal)/CalorieGoal,1)*100)))*0.1,0))

Sheet Workout Log
A1: 🏋️ WORKOUT LOG
A2: Log every set. Volume, 1RM and PRs calculate automatically.
A4: Date | B4: Workout Type | C4: Exercise | D4: Sets | E4: Reps | F4: Weight Lifted (kg) | G4: Total Volume | H4: RPE | I4: PR Achieved | J4: Notes | K4: Est. 1RM | L4: Wk # | M4: Month | N4: Squat 1RM | O4: Bench 1RM | P4: Deadlift 1RM | R4: LIVE VOLUME & LOAD SNAPSHOT | V4: Squat Best | W4: Bench Best | X4: Deadlift Best | Y4: Total Best
A5: 46023 | B5: Powerlifting | C5: Back Squat | D5: 5 | E5: 5 | F5: 120 | G5: =IF(OR(D5="",E5="",F5=""),"",D5*E5*F5) -> 3000 | H5: 8 | I5: =IF(OR(C5="",K5=""),"","Yes") -> Yes | J5: EXAMPLE ROW — overwrite with your own data (or delete the values). | K5: =IF(OR(E5="",F5=""),"",F5*(1+E5/30)) -> 140 | L5: =IF(A5="","",INT((A5-StartDate)/7)+1) -> 1 | M5: =IF(A5="","",TEXT(A5,"mmm")) -> Jan | N5: =IFERROR(IF(ISNUMBER(SEARCH("squat",C5)),K5,""),"") -> 140 | O5: =IFERROR(IF(ISNUMBER(SEARCH("bench",C5)),K5,""),"") | P5: =IFERROR(IF(ISNUMBER(SEARCH("deadlift",C5)),K5,""),"") | V5: =IF(N5="",0,N5) -> 140 | W5: =IF(O5="",0,O5) -> 0 | X5: =IF(P5="",0,P5) -> 0 | Y5: =V5+W5+X5 -> 140
A6: 46023 | B6: Powerlifting | C6: Bench Press | D6: 5 | E6: 5 | F6: 85 | G6: =IF(OR(D6="",E6="",F6=""),"",D6*E6*F6) -> 2125 | H6: 8 | I6: =IF(OR(C6="",K6=""),"",IF(K6>=_xlfn.MAXIFS($K$5:K5,$C$5:C5,C6),"Yes","No")) -> Yes | K6: =IF(OR(E6="",F6=""),"",F6*(1+E6/30)) -> 99.166667 | L6: =IF(A6="","",INT((A6-StartDate)/7)+1) -> 1 | M6: =IF(A6="","",TEXT(A6,"mmm")) -> Jan | N6: =IFERROR(IF(ISNUMBER(SEARCH("squat",C6)),K6,""),"") | O6: =IFERROR(IF(ISNUMBER(SEARCH("bench",C6)),K6,""),"") -> 99.166667 | P6: =IFERROR(IF(ISNUMBER(SEARCH("deadlift",C6)),K6,""),"") | R6: This Week — Total Volume (kg) | T6: =SUMIFS($G$5:$G$504,$L$5:$L$504,INT((TODAY()-StartDate)/7)+1) -> 0 | V6: =MAX(V5,IF(N6="",0,N6)) -> 140 | W6: =MAX(W5,IF(O6="",0,O6)) -> 99.166667 | X6: =MAX(X5,IF(P6="",0,P6)) -> 0 | Y6: =V6+W6+X6 -> 239.16667
A7: 46023 | B7: Powerlifting | C7: Deadlift | D7: 3 | E7: 3 | F7: 150 | G7: =IF(OR(D7="",E7="",F7=""),"",D7*E7*F7) -> 1350 | H7: 9 | I7: =IF(OR(C7="",K7=""),"",IF(K7>=_xlfn.MAXIFS($K$5:K6,$C$5:C6,C7),"Yes","No")) -> Yes | J7: New deadlift PR | K7: =IF(OR(E7="",F7=""),"",F7*(1+E7/30)) -> 165 | L7: =IF(A7="","",INT((A7-StartDate)/7)+1) -> 1 | M7: =IF(A7="","",TEXT(A7,"mmm")) -> Jan | N7: =IFERROR(IF(ISNUMBER(SEARCH("squat",C7)),K7,""),"") | O7: =IFERROR(IF(ISNUMBER(SEARCH("bench",C7)),K7,""),"") | P7: =IFERROR(IF(ISNUMBER(SEARCH("deadlift",C7)),K7,""),"") -> 165 | R7: This Week — Avg Intensity (RPE) | T7: =IFERROR(AVERAGEIFS($H$5:$H$504,$L$5:$L$504,INT((TODAY()-StartDate)/7)+1),0) -> 0 | V7: =MAX(V6,IF(N7="",0,N7)) -> 140 | W7: =MAX(W6,IF(O7="",0,O7)) -> 99.166667 | X7: =MAX(X6,IF(P7="",0,P7)) -> 165 | Y7: =V7+W7+X7 -> 404.16667
A8: 46023 | B8: Powerlifting | C8: Back Squat | D8: 1 | E8: 1 | F8: 140 | G8: =IF(OR(D8="",E8="",F8=""),"",D8*E8*F8) -> 140 | H8: 9 | I8: =IF(OR(C8="",K8=""),"",IF(K8>=_xlfn.MAXIFS($K$5:K7,$C$5:C7,C8),"Yes","No")) -> Yes | J8: Top single | K8: =IF(OR(E8="",F8=""),"",F8*(1+E8/30)) -> 144.66667 | L8: =IF(A8="","",INT((A8-StartDate)/7)+1) -> 1 | M8: =IF(A8="","",TEXT(A8,"mmm")) -> Jan | N8: =IFERROR(IF(ISNUMBER(SEARCH("squat",C8)),K8,""),"") -> 144.66667 | O8: =IFERROR(IF(ISNUMBER(SEARCH("bench",C8)),K8,""),"") | P8: =IFERROR(IF(ISNUMBER(SEARCH("deadlift",C8)),K8,""),"") | R8: This Week — Training Load | T8: =IFERROR(ROUND(SUMIFS($G$5:$G$504,$L$5:$L$504,INT((TODAY()-StartDate)/7)+1)*AVERAGEIFS($H$5:$H$504,$L$5:$L$504,INT((TODAY()-StartDate)/7)+1)/10,0),0) -> 0 | V8: =MAX(V7,IF(N8="",0,N8)) -> 144.66667 | W8: =MAX(W7,IF(O8="",0,O8)) -> 99.166667 | X8: =MAX(X7,IF(P8="",0,P8)) -> 165 | Y8: =V8+W8+X8 -> 408.83333
A9: 46023 | B9: Powerlifting | C9: Bench Press | D9: 1 | E9: 1 | F9: 95 | G9: =IF(OR(D9="",E9="",F9=""),"",D9*E9*F9) -> 95 | H9: 9 | I9: =IF(OR(C9="",K9=""),"",IF(K9>=_xlfn.MAXIFS($K$5:K8,$C$5:C8,C9),"Yes","No")) -> No | J9: Top single | K9: =IF(OR(E9="",F9=""),"",F9*(1+E9/30)) -> 98.166667 | L9: =IF(A9="","",INT((A9-StartDate)/7)+1) -> 1 | M9: =IF(A9="","",TEXT(A9,"mmm")) -> Jan | N9: =IFERROR(IF(ISNUMBER(SEARCH("squat",C9)),K9,""),"") | O9: =IFERROR(IF(ISNUMBER(SEARCH("bench",C9)),K9,""),"") -> 98.166667 | P9: =IFERROR(IF(ISNUMBER(SEARCH("deadlift",C9)),K9,""),"") | R9: This Month — Total Volume (kg) | T9: =SUMIFS($G$5:$G$504,$M$5:$M$504,TEXT(TODAY(),"mmm")) -> 0 | V9: =MAX(V8,IF(N9="",0,N9)) -> 144.66667 | W9: =MAX(W8,IF(O9="",0,O9)) -> 99.166667 | X9: =MAX(X8,IF(P9="",0,P9)) -> 165 | Y9: =V9+W9+X9 -> 408.83333
A10: 46023 | B10: Powerlifting | C10: Deadlift | D10: 1 | E10: 1 | F10: 170 | G10: =IF(OR(D10="",E10="",F10=""),"",D10*E10*F10) -> 170 | H10: 9 | I10: =IF(OR(C10="",K10=""),"",IF(K10>=_xlfn.MAXIFS($K$5:K9,$C$5:C9,C10),"Yes","No")) -> Yes | J10: Top single | K10: =IF(OR(E10="",F10=""),"",F10*(1+E10/30)) -> 175.66667 | L10: =IF(A10="","",INT((A10-StartDate)/7)+1) -> 1 | M10: =IF(A10="","",TEXT(A10,"mmm")) -> Jan | N10: =IFERROR(IF(ISNUMBER(SEARCH("squat",C10)),K10,""),"") | O10: =IFERROR(IF(ISNUMBER(SEARCH("bench",C10)),K10,""),"") | P10: =IFERROR(IF(ISNUMBER(SEARCH("deadlift",C10)),K10,""),"") -> 175.66667 | R10: This Month — Avg Intensity (RPE) | T10: =IFERROR(AVERAGEIFS($H$5:$H$504,$M$5:$M$504,TEXT(TODAY(),"mmm")),0) -> 0 | V10: =MAX(V9,IF(N10="",0,N10)) -> 144.66667 | W10: =MAX(W9,IF(O10="",0,O10)) -> 99.166667 | X10: =MAX(X9,IF(P10="",0,P10)) -> 175.66667 | Y10: =V10+W10+X10 -> 419.5
G11: =IF(OR(D11="",E11="",F11=""),"",D11*E11*F11) | I11: =IF(OR(C11="",K11=""),"",IF(K11>=_xlfn.MAXIFS($K$5:K10,$C$5:C10,C11),"Yes","No")) | K11: =IF(OR(E11="",F11=""),"",F11*(1+E11/30)) | L11: =IF(A11="","",INT((A11-StartDate)/7)+1) | M11: =IF(A11="","",TEXT(A11,"mmm")) | N11: =IFERROR(IF(ISNUMBER(SEARCH("squat",C11)),K11,""),"") | O11: =IFERROR(IF(ISNUMBER(SEARCH("bench",C11)),K11,""),"") | P11: =IFERROR(IF(ISNUMBER(SEARCH("deadlift",C11)),K11,""),"") | R11: Lifetime Total Volume (kg) | T11: =SUM($G$5:$G$504) -> 6880 | V11: =MAX(V10,IF(N11="",0,N11)) -> 144.66667 | W11: =MAX(W10,IF(O11="",0,O11)) -> 99.166667 | X11: =MAX(X10,IF(P11="",0,P11)) -> 175.66667 | Y11: =V11+W11+X11 -> 419.5
G12: =IF(OR(D12="",E12="",F12=""),"",D12*E12*F12) | I12: =IF(OR(C12="",K12=""),"",IF(K12>=_xlfn.MAXIFS($K$5:K11,$C$5:C11,C12),"Yes","No")) | K12: =IF(OR(E12="",F12=""),"",F12*(1+E12/30)) | L12: =IF(A12="","",INT((A12-StartDate)/7)+1) | M12: =IF(A12="","",TEXT(A12,"mmm")) | N12: =IFERROR(IF(ISNUMBER(SEARCH("squat",C12)),K12,""),"") | O12: =IFERROR(IF(ISNUMBER(SEARCH("bench",C12)),K12,""),"") | P12: =IFERROR(IF(ISNUMBER(SEARCH("deadlift",C12)),K12,""),"") | V12: =MAX(V11,IF(N12="",0,N12)) -> 144.66667 | W12: =MAX(W11,IF(O12="",0,O12)) -> 99.166667 | X12: =MAX(X11,IF(P12="",0,P12)) -> 175.66667 | Y12: =V12+W12+X12 -> 419.5
G13: =IF(OR(D13="",E13="",F13=""),"",D13*E13*F13) | I13: =IF(OR(C13="",K13=""),"",IF(K13>=_xlfn.MAXIFS($K$5:K12,$C$5:C12,C13),"Yes","No")) | K13: =IF(OR(E13="",F13=""),"",F13*(1+E13/30)) | L13: =IF(A13="","",INT((A13-StartDate)/7)+1) | M13: =IF(A13="","",TEXT(A13,"mmm")) | N13: =IFERROR(IF(ISNUMBER(SEARCH("squat",C13)),K13,""),"") | O13: =IFERROR(IF(ISNUMBER(SEARCH("bench",C13)),K13,""),"") | P13: =IFERROR(IF(ISNUMBER(SEARCH("deadlift",C13)),K13,""),"") | V13: =MAX(V12,IF(N13="",0,N13)) -> 144.66667 | W13: =MAX(W12,IF(O13="",0,O13)) -> 99.166667 | X13: =MAX(X12,IF(P13="",0,P13)) -> 175.66667 | Y13: =V13+W13+X13 -> 419.5
G14: =IF(OR(D14="",E14="",F14=""),"",D14*E14*F14) | I14: =IF(OR(C14="",K14=""),"",IF(K14>=_xlfn.MAXIFS($K$5:K13,$C$5:C13,C14),"Yes","No")) | K14: =IF(OR(E14="",F14=""),"",F14*(1+E14/30)) | L14: =IF(A14="","",INT((A14-StartDate)/7)+1) | M14: =IF(A14="","",TEXT(A14,"mmm")) | N14: =IFERROR(IF(ISNUMBER(SEARCH("squat",C14)),K14,""),"") | O14: =IFERROR(IF(ISNUMBER(SEARCH("bench",C14)),K14,""),"") | P14: =IFERROR(IF(ISNUMBER(SEARCH("deadlift",C14)),K14,""),"") | V14: =MAX(V13,IF(N14="",0,N14)) -> 144.66667 | W14: =MAX(W13,IF(O14="",0,O14)) -> 99.166667 | X14: =MAX(X13,IF(P14="",0,P14)) -> 175.66667 | Y14: =V14+W14+X14 -> 419.5
G15: =IF(OR(D15="",E15="",F15=""),"",D15*E15*F15) | I15: =IF(OR(C15="",K15=""),"",IF(K15>=_xlfn.MAXIFS($K$5:K14,$C$5:C14,C15),"Yes","No")) | K15: =IF(OR(E15="",F15=""),"",F15*(1+E15/30)) | L15: =IF(A15="","",INT((A15-StartDate)/7)+1) | M15: =IF(A15="","",TEXT(A15,"mmm")) | N15: =IFERROR(IF(ISNUMBER(SEARCH("squat",C15)),K15,""),"") | O15: =IFERROR(IF(ISNUMBER(SEARCH("bench",C15)),K15,""),"") | P15: =IFERROR(IF(ISNUMBER(SEARCH("deadlift",C15)),K15,""),"") | V15: =MAX(V14,IF(N15="",0,N15)) -> 144.66667 | W15: =MAX(W14,IF(O15="",0,O15)) -> 99.166667 | X15: =MAX(X14,IF(P15="",0,P15)) -> 175.66667 | Y15: =V15+W15+X15 -> 419.5
G16: =IF(OR(D16="",E16="",F16=""),"",D16*E16*F16) | I16: =IF(OR(C16="",K16=""),"",IF(K16>=_xlfn.MAXIFS($K$5:K15,$C$5:C15,C16),"Yes","No")) | K16: =IF(OR(E16="",F16=""),"",F16*(1+E16/30)) | L16: =IF(A16="","",INT((A16-StartDate)/7)+1) | M16: =IF(A16="","",TEXT(A16,"mmm")) | N16: =IFERROR(IF(ISNUMBER(SEARCH("squat",C16)),K16,""),"") | O16: =IFERROR(IF(ISNUMBER(SEARCH("bench",C16)),K16,""),"") | P16: =IFERROR(IF(ISNUMBER(SEARCH("deadlift",C16)),K16,""),"") | V16: =MAX(V15,IF(N16="",0,N16)) -> 144.66667 | W16: =MAX(W15,IF(O16="",0,O16)) -> 99.166667 | X16: =MAX(X15,IF(P16="",0,P16)) -> 175.66667 | Y16: =V16+W16+X16 -> 419.5
G17: =IF(OR(D17="",E17="",F17=""),"",D17*E17*F17) | I17: =IF(OR(C17="",K17=""),"",IF(K17>=_xlfn.MAXIFS($K$5:K16,$C$5:C16,C17),"Yes","No")) | K17: =IF(OR(E17="",F17=""),"",F17*(1+E17/30)) | L17: =IF(A17="","",INT((A17-StartDate)/7)+1) | M17: =IF(A17="","",TEXT(A17,"mmm")) | N17: =IFERROR(IF(ISNUMBER(SEARCH("squat",C17)),K17,""),"") | O17: =IFERROR(IF(ISNUMBER(SEARCH("bench",C17)),K17,""),"") | P17: =IFERROR(IF(ISNUMBER(SEARCH("deadlift",C17)),K17,""),"") | V17: =MAX(V16,IF(N17="",0,N17)) -> 144.66667 | W17: =MAX(W16,IF(O17="",0,O17)) -> 99.166667 | X17: =MAX(X16,IF(P17="",0,P17)) -> 175.66667 | Y17: =V17+W17+X17 -> 419.5
G18: =IF(OR(D18="",E18="",F18=""),"",D18*E18*F18) | I18: =IF(OR(C18="",K18=""),"",IF(K18>=_xlfn.MAXIFS($K$5:K17,$C$5:C17,C18),"Yes","No")) | K18: =IF(OR(E18="",F18=""),"",F18*(1+E18/30)) | L18: =IF(A18="","",INT((A18-StartDate)/7)+1) | M18: =IF(A18="","",TEXT(A18,"mmm")) | N18: =IFERROR(IF(ISNUMBER(SEARCH("squat",C18)),K18,""),"") | O18: =IFERROR(IF(ISNUMBER(SEARCH("bench",C18)),K18,""),"") | P18: =IFERROR(IF(ISNUMBER(SEARCH("deadlift",C18)),K18,""),"") | V18: =MAX(V17,IF(N18="",0,N18)) -> 144.66667 | W18: =MAX(W17,IF(O18="",0,O18)) -> 99.166667 | X18: =MAX(X17,IF(P18="",0,P18)) -> 175.66667 | Y18: =V18+W18+X18 -> 419.5
G19: =IF(OR(D19="",E19="",F19=""),"",D19*E19*F19) | I19: =IF(OR(C19="",K19=""),"",IF(K19>=_xlfn.MAXIFS($K$5:K18,$C$5:C18,C19),"Yes","No")) | K19: =IF(OR(E19="",F19=""),"",F19*(1+E19/30)) | L19: =IF(A19="","",INT((A19-StartDate)/7)+1) | M19: =IF(A19="","",TEXT(A19,"mmm")) | N19: =IFERROR(IF(ISNUMBER(SEARCH("squat",C19)),K19,""),"") | O19: =IFERROR(IF(ISNUMBER(SEARCH("bench",C19)),K19,""),"") | P19: =IFERROR(IF(ISNUMBER(SEARCH("deadlift",C19)),K19,""),"") | V19: =MAX(V18,IF(N19="",0,N19)) -> 144.66667 | W19: =MAX(W18,IF(O19="",0,O19)) -> 99.166667 | X19: =MAX(X18,IF(P19="",0,P19)) -> 175.66667 | Y19: =V19+W19+X19 -> 419.5
G20: =IF(OR(D20="",E20="",F20=""),"",D20*E20*F20) | I20: =IF(OR(C20="",K20=""),"",IF(K20>=_xlfn.MAXIFS($K$5:K19,$C$5:C19,C20),"Yes","No")) | K20: =IF(OR(E20="",F20=""),"",F20*(1+E20/30)) | L20: =IF(A20="","",INT((A20-StartDate)/7)+1) | M20: =IF(A20="","",TEXT(A20,"mmm")) | N20: =IFERROR(IF(ISNUMBER(SEARCH("squat",C20)),K20,""),"") | O20: =IFERROR(IF(ISNUMBER(SEARCH("bench",C20)),K20,""),"") | P20: =IFERROR(IF(ISNUMBER(SEARCH("deadlift",C20)),K20,""),"") | V20: =MAX(V19,IF(N20="",0,N20)) -> 144.66667 | W20: =MAX(W19,IF(O20="",0,O20)) -> 99.166667 | X20: =MAX(X19,IF(P20="",0,P20)) -> 175.66667 | Y20: =V20+W20+X20 -> 419.5
G21: =IF(OR(D21="",E21="",F21=""),"",D21*E21*F21) | I21: =IF(OR(C21="",K21=""),"",IF(K21>=_xlfn.MAXIFS($K$5:K20,$C$5:C20,C21),"Yes","No")) | K21: =IF(OR(E21="",F21=""),"",F21*(1+E21/30)) | L21: =IF(A21="","",INT((A21-StartDate)/7)+1) | M21: =IF(A21="","",TEXT(A21,"mmm")) | N21: =IFERROR(IF(ISNUMBER(SEARCH("squat",C21)),K21,""),"") | O21: =IFERROR(IF(ISNUMBER(SEARCH("bench",C21)),K21,""),"") | P21: =IFERROR(IF(ISNUMBER(SEARCH("deadlift",C21)),K21,""),"") | V21: =MAX(V20,IF(N21="",0,N21)) -> 144.66667 | W21: =MAX(W20,IF(O21="",0,O21)) -> 99.166667 | X21: =MAX(X20,IF(P21="",0,P21)) -> 175.66667 | Y21: =V21+W21+X21 -> 419.5
G22: =IF(OR(D22="",E22="",F22=""),"",D22*E22*F22) | I22: =IF(OR(C22="",K22=""),"",IF(K22>=_xlfn.MAXIFS($K$5:K21,$C$5:C21,C22),"Yes","No")) | K22: =IF(OR(E22="",F22=""),"",F22*(1+E22/30)) | L22: =IF(A22="","",INT((A22-StartDate)/7)+1) | M22: =IF(A22="","",TEXT(A22,"mmm")) | N22: =IFERROR(IF(ISNUMBER(SEARCH("squat",C22)),K22,""),"") | O22: =IFERROR(IF(ISNUMBER(SEARCH("bench",C22)),K22,""),"") | P22: =IFERROR(IF(ISNUMBER(SEARCH("deadlift",C22)),K22,""),"") | V22: =MAX(V21,IF(N22="",0,N22)) -> 144.66667 | W22: =MAX(W21,IF(O22="",0,O22)) -> 99.166667 | X22: =MAX(X21,IF(P22="",0,P22)) -> 175.66667 | Y22: =V22+W22+X22 -> 419.5
G23: =IF(OR(D23="",E23="",F23=""),"",D23*E23*F23) | I23: =IF(OR(C23="",K23=""),"",IF(K23>=_xlfn.MAXIFS($K$5:K22,$C$5:C22,C23),"Yes","No")) | K23: =IF(OR(E23="",F23=""),"",F23*(1+E23/30)) | L23: =IF(A23="","",INT((A23-StartDate)/7)+1) | M23: =IF(A23="","",TEXT(A23,"mmm")) | N23: =IFERROR(IF(ISNUMBER(SEARCH("squat",C23)),K23,""),"") | O23: =IFERROR(IF(ISNUMBER(SEARCH("bench",C23)),K23,""),"") | P23: =IFERROR(IF(ISNUMBER(SEARCH("deadlift",C23)),K23,""),"") | V23: =MAX(V22,IF(N23="",0,N23)) -> 144.66667 | W23: =MAX(W22,IF(O23="",0,O23)) -> 99.166667 | X23: =MAX(X22,IF(P23="",0,P23)) -> 175.66667 | Y23: =V23+W23+X23 -> 419.5
... G504: =IF(OR(D504="",E504="",F504=""),"",D504*E504*F504) | I504: =IF(OR(C504="",K504=""),"",IF(K504>=_xlfn.MAXIFS($K$5:K503,$C$5:C503,C504),"Yes","No")) | K504: =IF(OR(E504="",F504=""),"",F504*(1+E504/30)) | L504: =IF(A504="","",INT((A504-StartDate)/7)+1) | M504: =IF(A504="","",TEXT(A504,"mmm")) | N504: =IFERROR(IF(ISNUMBER(SEARCH("squat",C504)),K504,""),"") | O504: =IFERROR(IF(ISNUMBER(SEARCH("bench",C504)),K504,""),"") | P504: =IFERROR(IF(ISNUMBER(SEARCH("deadlift",C504)),K504,""),"") | V504: =MAX(V503,IF(N504="",0,N504)) -> 144.66667 | W504: =MAX(W503,IF(O504="",0,O504)) -> 99.166667 | X504: =MAX(X503,IF(P504="",0,P504)) -> 175.66667 | Y504: =V504+W504+X504 -> 419.5

Sheet Cardio & HYROX Log
A1: 🏃 CARDIO & HYROX LOG
A2: Distance-based pace calculates automatically. Leave distance blank for rep-based movements.
A4: Date | B4: Exercise | C4: Distance (km) | D4: Time (h:mm:ss) | E4: Pace (min/km) | F4: Calories | G4: Avg HR | H4: Max HR | I4: Wk # | J4: Month | L4: LIVE CARDIO SNAPSHOT
A5: 46023 | B5: Running | C5: 5 | D5: 0.017361111 | E5: =IFERROR(IF(OR(C5="",C5=0,D5=""),"",D5*1440/C5),"") -> 5 | F5: 320 | G5: 150 | H5: 175 | I5: =IF(A5="","",INT((A5-StartDate)/7)+1) -> 1 | J5: =IF(A5="","",TEXT(A5,"mmm")) -> Jan
E6: =IFERROR(IF(OR(C6="",C6=0,D6=""),"",D6*1440/C6),"") | I6: =IF(A6="","",INT((A6-StartDate)/7)+1) | J6: =IF(A6="","",TEXT(A6,"mmm")) | L6: This Week — Total Distance (km) | N6: =SUMIFS($C$5:$C$304,$I$5:$I$304,INT((TODAY()-StartDate)/7)+1) -> 0
E7: =IFERROR(IF(OR(C7="",C7=0,D7=""),"",D7*1440/C7),"") | I7: =IF(A7="","",INT((A7-StartDate)/7)+1) | J7: =IF(A7="","",TEXT(A7,"mmm")) | L7: This Week — Total Calories | N7: =SUMIFS($F$5:$F$304,$I$5:$I$304,INT((TODAY()-StartDate)/7)+1) -> 0
E8: =IFERROR(IF(OR(C8="",C8=0,D8=""),"",D8*1440/C8),"") | I8: =IF(A8="","",INT((A8-StartDate)/7)+1) | J8: =IF(A8="","",TEXT(A8,"mmm")) | L8: This Week — Sessions | N8: =COUNTIFS($I$5:$I$304,INT((TODAY()-StartDate)/7)+1,$B$5:$B$304,"<>") -> 0
E9: =IFERROR(IF(OR(C9="",C9=0,D9=""),"",D9*1440/C9),"") | I9: =IF(A9="","",INT((A9-StartDate)/7)+1) | J9: =IF(A9="","",TEXT(A9,"mmm")) | L9: This Week — Avg Pace (min/km) | N9: =IFERROR(AVERAGEIFS($E$5:$E$304,$I$5:$I$304,INT((TODAY()-StartDate)/7)+1,$E$5:$E$304,">0"),0) -> 0
E10: =IFERROR(IF(OR(C10="",C10=0,D10=""),"",D10*1440/C10),"") | I10: =IF(A10="","",INT((A10-StartDate)/7)+1) | J10: =IF(A10="","",TEXT(A10,"mmm")) | L10: This Month — Total Distance (km) | N10: =SUMIFS($C$5:$C$304,$J$5:$J$304,TEXT(TODAY(),"mmm")) -> 0
E11: =IFERROR(IF(OR(C11="",C11=0,D11=""),"",D11*1440/C11),"") | I11: =IF(A11="","",INT((A11-StartDate)/7)+1) | J11: =IF(A11="","",TEXT(A11,"mmm")) | L11: This Month — Total Calories | N11: =SUMIFS($F$5:$F$304,$J$5:$J$304,TEXT(TODAY(),"mmm")) -> 0
E12: =IFERROR(IF(OR(C12="",C12=0,D12=""),"",D12*1440/C12),"") | I12: =IF(A12="","",INT((A12-StartDate)/7)+1) | J12: =IF(A12="","",TEXT(A12,"mmm"))
E13: =IFERROR(IF(OR(C13="",C13=0,D13=""),"",D13*1440/C13),"") | I13: =IF(A13="","",INT((A13-StartDate)/7)+1) | J13: =IF(A13="","",TEXT(A13,"mmm"))
E14: =IFERROR(IF(OR(C14="",C14=0,D14=""),"",D14*1440/C14),"") | I14: =IF(A14="","",INT((A14-StartDate)/7)+1) | J14: =IF(A14="","",TEXT(A14,"mmm"))
E15: =IFERROR(IF(OR(C15="",C15=0,D15=""),"",D15*1440/C15),"") | I15: =IF(A15="","",INT((A15-StartDate)/7)+1) | J15: =IF(A15="","",TEXT(A15,"mmm"))
E16: =IFERROR(IF(OR(C16="",C16=0,D16=""),"",D16*1440/C16),"") | I16: =IF(A16="","",INT((A16-StartDate)/7)+1) | J16: =IF(A16="","",TEXT(A16,"mmm"))
E17: =IFERROR(IF(OR(C17="",C17=0,D17=""),"",D17*1440/C17),"") | I17: =IF(A17="","",INT((A17-StartDate)/7)+1) | J17: =IF(A17="","",TEXT(A17,"mmm"))
E18: =IFERROR(IF(OR(C18="",C18=0,D18=""),"",D18*1440/C18),"") | I18: =IF(A18="","",INT((A18-StartDate)/7)+1) | J18: =IF(A18="","",TEXT(A18,"mmm"))
E19: =IFERROR(IF(OR(C19="",C19=0,D19=""),"",D19*1440/C19),"") | I19: =IF(A19="","",INT((A19-StartDate)/7)+1) | J19: =IF(A19="","",TEXT(A19,"mmm"))
E20: =IFERROR(IF(OR(C20="",C20=0,D20=""),"",D20*1440/C20),"") | I20: =IF(A20="","",INT((A20-StartDate)/7)+1) | J20: =IF(A20="","",TEXT(A20,"mmm"))
E21: =IFERROR(IF(OR(C21="",C21=0,D21=""),"",D21*1440/C21),"") | I21: =IF(A21="","",INT((A21-StartDate)/7)+1) | J21: =IF(A21="","",TEXT(A21,"mmm"))
E22: =IFERROR(IF(OR(C22="",C22=0,D22=""),"",D22*1440/C22),"") | I22: =IF(A22="","",INT((A22-StartDate)/7)+1) | J22: =IF(A22="","",TEXT(A22,"mmm"))
E23: =IFERROR(IF(OR(C23="",C23=0,D23=""),"",D23*1440/C23),"") | I23: =IF(A23="","",INT((A23-StartDate)/7)+1) | J23: =IF(A23="","",TEXT(A23,"mmm"))
... E304: =IFERROR(IF(OR(C304="",C304=0,D304=""),"",D304*1440/C304),"") | I304: =IF(A304="","",INT((A304-StartDate)/7)+1) | J304: =IF(A304="","",TEXT(A304,"mmm"))

Sheet Recovery Tracker
A1: 🛌 RECOVERY TRACKER
A2: Sleep auto-pulls from Daily Tracker. Recovery Score (0-100) calculates automatically.
A4: Date | B4: Sleep (hrs) | C4: HRV (ms) | D4: Resting HR (bpm) | E4: Recovery Score | F4: Muscle Soreness | G4: Stress Level | H4: Fatigue | I4: Notes
A5: ='Daily Tracker'!A5 -> 46023 | B5: =IF('Daily Tracker'!F5="","",'Daily Tracker'!F5) -> 7.5 | C5: 62 | D5: 52 | E5: =IFERROR(IF(COUNT(B5,C5,D5,F5,G5,H5)=0,"",ROUND((IF(B5="",70,MIN(B5/SleepGoal,1)*100))*0.25+(IF(C5="",70,MIN(C5/HRVGoal,1)*100))*0.2+(IF(D5="",70,MAX(0,MIN(1,(RHRPoor-D5)/(RHRPoor-RHRExcellent)))*100))*0.2+(IF(F5="",70,(5-F5)/4*100))*0.15+(IF(G5="",70,(5-G5)/4*100))*0.1+(IF(H5="",70,(5-H5)/4*100))*0.1,0)),"") -> 84 | F5: 2 | G5: 2 | H5: 2 | I5: EXAMPLE ROW — overwrite with your own data (or delete the values).
A6: ='Daily Tracker'!A6 -> 46024 | B6: =IF('Daily Tracker'!F6="","",'Daily Tracker'!F6) | E6: =IFERROR(IF(COUNT(B6,C6,D6,F6,G6,H6)=0,"",ROUND((IF(B6="",70,MIN(B6/SleepGoal,1)*100))*0.25+(IF(C6="",70,MIN(C6/HRVGoal,1)*100))*0.2+(IF(D6="",70,MAX(0,MIN(1,(RHRPoor-D6)/(RHRPoor-RHRExcellent)))*100))*0.2+(IF(F6="",70,(5-F6)/4*100))*0.15+(IF(G6="",70,(5-G6)/4*100))*0.1+(IF(H6="",70,(5-H6)/4*100))*0.1,0)),"")
A7: ='Daily Tracker'!A7 -> 46025 | B7: =IF('Daily Tracker'!F7="","",'Daily Tracker'!F7) | E7: =IFERROR(IF(COUNT(B7,C7,D7,F7,G7,H7)=0,"",ROUND((IF(B7="",70,MIN(B7/SleepGoal,1)*100))*0.25+(IF(C7="",70,MIN(C7/HRVGoal,1)*100))*0.2+(IF(D7="",70,MAX(0,MIN(1,(RHRPoor-D7)/(RHRPoor-RHRExcellent)))*100))*0.2+(IF(F7="",70,(5-F7)/4*100))*0.15+(IF(G7="",70,(5-G7)/4*100))*0.1+(IF(H7="",70,(5-H7)/4*100))*0.1,0)),"")
A8: ='Daily Tracker'!A8 -> 46026 | B8: =IF('Daily Tracker'!F8="","",'Daily Tracker'!F8) | E8: =IFERROR(IF(COUNT(B8,C8,D8,F8,G8,H8)=0,"",ROUND((IF(B8="",70,MIN(B8/SleepGoal,1)*100))*0.25+(IF(C8="",70,MIN(C8/HRVGoal,1)*100))*0.2+(IF(D8="",70,MAX(0,MIN(1,(RHRPoor-D8)/(RHRPoor-RHRExcellent)))*100))*0.2+(IF(F8="",70,(5-F8)/4*100))*0.15+(IF(G8="",70,(5-G8)/4*100))*0.1+(IF(H8="",70,(5-H8)/4*100))*0.1,0)),"")
A9: ='Daily Tracker'!A9 -> 46027 | B9: =IF('Daily Tracker'!F9="","",'Daily Tracker'!F9) | E9: =IFERROR(IF(COUNT(B9,C9,D9,F9,G9,H9)=0,"",ROUND((IF(B9="",70,MIN(B9/SleepGoal,1)*100))*0.25+(IF(C9="",70,MIN(C9/HRVGoal,1)*100))*0.2+(IF(D9="",70,MAX(0,MIN(1,(RHRPoor-D9)/(RHRPoor-RHRExcellent)))*100))*0.2+(IF(F9="",70,(5-F9)/4*100))*0.15+(IF(G9="",70,(5-G9)/4*100))*0.1+(IF(H9="",70,(5-H9)/4*100))*0.1,0)),"")
A10: ='Daily Tracker'!A10 -> 46028 | B10: =IF('Daily Tracker'!F10="","",'Daily Tracker'!F10) | E10: =IFERROR(IF(COUNT(B10,C10,D10,F10,G10,H10)=0,"",ROUND((IF(B10="",70,MIN(B10/SleepGoal,1)*100))*0.25+(IF(C10="",70,MIN(C10/HRVGoal,1)*100))*0.2+(IF(D10="",70,MAX(0,MIN(1,(RHRPoor-D10)/(RHRPoor-RHRExcellent)))*100))*0.2+(IF(F10="",70,(5-F10)/4*100))*0.15+(IF(G10="",70,(5-G10)/4*100))*0.1+(IF(H10="",70,(5-H10)/4*100))*0.1,0)),"")
A11: ='Daily Tracker'!A11 -> 46029 | B11: =IF('Daily Tracker'!F11="","",'Daily Tracker'!F11) | E11: =IFERROR(IF(COUNT(B11,C11,D11,F11,G11,H11)=0,"",ROUND((IF(B11="",70,MIN(B11/SleepGoal,1)*100))*0.25+(IF(C11="",70,MIN(C11/HRVGoal,1)*100))*0.2+(IF(D11="",70,MAX(0,MIN(1,(RHRPoor-D11)/(RHRPoor-RHRExcellent)))*100))*0.2+(IF(F11="",70,(5-F11)/4*100))*0.15+(IF(G11="",70,(5-G11)/4*100))*0.1+(IF(H11="",70,(5-H11)/4*100))*0.1,0)),"")
A12: ='Daily Tracker'!A12 -> 46030 | B12: =IF('Daily Tracker'!F12="","",'Daily Tracker'!F12) | E12: =IFERROR(IF(COUNT(B12,C12,D12,F12,G12,H12)=0,"",ROUND((IF(B12="",70,MIN(B12/SleepGoal,1)*100))*0.25+(IF(C12="",70,MIN(C12/HRVGoal,1)*100))*0.2+(IF(D12="",70,MAX(0,MIN(1,(RHRPoor-D12)/(RHRPoor-RHRExcellent)))*100))*0.2+(IF(F12="",70,(5-F12)/4*100))*0.15+(IF(G12="",70,(5-G12)/4*100))*0.1+(IF(H12="",70,(5-H12)/4*100))*0.1,0)),"")
A13: ='Daily Tracker'!A13 -> 46031 | B13: =IF('Daily Tracker'!F13="","",'Daily Tracker'!F13) | E13: =IFERROR(IF(COUNT(B13,C13,D13,F13,G13,H13)=0,"",ROUND((IF(B13="",70,MIN(B13/SleepGoal,1)*100))*0.25+(IF(C13="",70,MIN(C13/HRVGoal,1)*100))*0.2+(IF(D13="",70,MAX(0,MIN(1,(RHRPoor-D13)/(RHRPoor-RHRExcellent)))*100))*0.2+(IF(F13="",70,(5-F13)/4*100))*0.15+(IF(G13="",70,(5-G13)/4*100))*0.1+(IF(H13="",70,(5-H13)/4*100))*0.1,0)),"")
A14: ='Daily Tracker'!A14 -> 46032 | B14: =IF('Daily Tracker'!F14="","",'Daily Tracker'!F14) | E14: =IFERROR(IF(COUNT(B14,C14,D14,F14,G14,H14)=0,"",ROUND((IF(B14="",70,MIN(B14/SleepGoal,1)*100))*0.25+(IF(C14="",70,MIN(C14/HRVGoal,1)*100))*0.2+(IF(D14="",70,MAX(0,MIN(1,(RHRPoor-D14)/(RHRPoor-RHRExcellent)))*100))*0.2+(IF(F14="",70,(5-F14)/4*100))*0.15+(IF(G14="",70,(5-G14)/4*100))*0.1+(IF(H14="",70,(5-H14)/4*100))*0.1,0)),"")
A15: ='Daily Tracker'!A15 -> 46033 | B15: =IF('Daily Tracker'!F15="","",'Daily Tracker'!F15) | E15: =IFERROR(IF(COUNT(B15,C15,D15,F15,G15,H15)=0,"",ROUND((IF(B15="",70,MIN(B15/SleepGoal,1)*100))*0.25+(IF(C15="",70,MIN(C15/HRVGoal,1)*100))*0.2+(IF(D15="",70,MAX(0,MIN(1,(RHRPoor-D15)/(RHRPoor-RHRExcellent)))*100))*0.2+(IF(F15="",70,(5-F15)/4*100))*0.15+(IF(G15="",70,(5-G15)/4*100))*0.1+(IF(H15="",70,(5-H15)/4*100))*0.1,0)),"")
A16: ='Daily Tracker'!A16 -> 46034 | B16: =IF('Daily Tracker'!F16="","",'Daily Tracker'!F16) | E16: =IFERROR(IF(COUNT(B16,C16,D16,F16,G16,H16)=0,"",ROUND((IF(B16="",70,MIN(B16/SleepGoal,1)*100))*0.25+(IF(C16="",70,MIN(C16/HRVGoal,1)*100))*0.2+(IF(D16="",70,MAX(0,MIN(1,(RHRPoor-D16)/(RHRPoor-RHRExcellent)))*100))*0.2+(IF(F16="",70,(5-F16)/4*100))*0.15+(IF(G16="",70,(5-G16)/4*100))*0.1+(IF(H16="",70,(5-H16)/4*100))*0.1,0)),"")
A17: ='Daily Tracker'!A17 -> 46035 | B17: =IF('Daily Tracker'!F17="","",'Daily Tracker'!F17) | E17: =IFERROR(IF(COUNT(B17,C17,D17,F17,G17,H17)=0,"",ROUND((IF(B17="",70,MIN(B17/SleepGoal,1)*100))*0.25+(IF(C17="",70,MIN(C17/HRVGoal,1)*100))*0.2+(IF(D17="",70,MAX(0,MIN(1,(RHRPoor-D17)/(RHRPoor-RHRExcellent)))*100))*0.2+(IF(F17="",70,(5-F17)/4*100))*0.15+(IF(G17="",70,(5-G17)/4*100))*0.1+(IF(H17="",70,(5-H17)/4*100))*0.1,0)),"")
... A369: ='Daily Tracker'!A369 -> 46387 | B369: =IF('Daily Tracker'!F369="","",'Daily Tracker'!F369) | E369: =IFERROR(IF(COUNT(B369,C369,D369,F369,G369,H369)=0,"",ROUND((IF(B369="",70,MIN(B369/SleepGoal,1)*100))*0.25+(IF(C369="",70,MIN(C369/HRVGoal,1)*100))*0.2+(IF(D369="",70,MAX(0,MIN(1,(RHRPoor-D369)/(RHRPoor-RHRExcellent)))*100))*0.2+(IF(F369="",70,(5-F369)/4*100))*0.15+(IF(G369="",70,(5-G369)/4*100))*0.1+(IF(H369="",70,(5-H369)/4*100))*0.1,0)),"")

Sheet Nutrition Tracker
A1: 🥗 NUTRITION TRACKER
A2: Water auto-pulls from Daily Tracker. Percent columns compare intake to your Goals & Settings targets.
A4: Date | B4: Calories | C4: Protein (g) | D4: Carbs (g) | E4: Fat (g) | F4: Fiber (g) | G4: Water (L) | H4: Calories % | I4: Protein % | J4: Carbs % | K4: Fat % | L4: Fiber % | M4: Water %
A5: ='Daily Tracker'!A5 -> 46023 | B5: 2850 | C5: 185 | D5: 310 | E5: 82 | F5: 29 | G5: =IF('Daily Tracker'!I5="","",'Daily Tracker'!I5) -> 4.2 | H5: =IF(B5="","",B5/CalorieGoal) -> 1.0178571 | I5: =IF(C5="","",C5/ProteinGoal) -> 1.15625 | J5: =IF(D5="","",D5/CarbGoal) -> 1.0333333 | K5: =IF(E5="","",E5/FatGoal) -> 1.025 | L5: =IF(F5="","",F5/FiberGoal) -> 0.96666667 | M5: =IF(G5="","",G5/WaterGoal) -> 1.05
A6: ='Daily Tracker'!A6 -> 46024 | G6: =IF('Daily Tracker'!I6="","",'Daily Tracker'!I6) | H6: =IF(B6="","",B6/CalorieGoal) | I6: =IF(C6="","",C6/ProteinGoal) | J6: =IF(D6="","",D6/CarbGoal) | K6: =IF(E6="","",E6/FatGoal) | L6: =IF(F6="","",F6/FiberGoal) | M6: =IF(G6="","",G6/WaterGoal)
A7: ='Daily Tracker'!A7 -> 46025 | G7: =IF('Daily Tracker'!I7="","",'Daily Tracker'!I7) | H7: =IF(B7="","",B7/CalorieGoal) | I7: =IF(C7="","",C7/ProteinGoal) | J7: =IF(D7="","",D7/CarbGoal) | K7: =IF(E7="","",E7/FatGoal) | L7: =IF(F7="","",F7/FiberGoal) | M7: =IF(G7="","",G7/WaterGoal)
A8: ='Daily Tracker'!A8 -> 46026 | G8: =IF('Daily Tracker'!I8="","",'Daily Tracker'!I8) | H8: =IF(B8="","",B8/CalorieGoal) | I8: =IF(C8="","",C8/ProteinGoal) | J8: =IF(D8="","",D8/CarbGoal) | K8: =IF(E8="","",E8/FatGoal) | L8: =IF(F8="","",F8/FiberGoal) | M8: =IF(G8="","",G8/WaterGoal)
A9: ='Daily Tracker'!A9 -> 46027 | G9: =IF('Daily Tracker'!I9="","",'Daily Tracker'!I9) | H9: =IF(B9="","",B9/CalorieGoal) | I9: =IF(C9="","",C9/ProteinGoal) | J9: =IF(D9="","",D9/CarbGoal) | K9: =IF(E9="","",E9/FatGoal) | L9: =IF(F9="","",F9/FiberGoal) | M9: =IF(G9="","",G9/WaterGoal)
A10: ='Daily Tracker'!A10 -> 46028 | G10: =IF('Daily Tracker'!I10="","",'Daily Tracker'!I10) | H10: =IF(B10="","",B10/CalorieGoal) | I10: =IF(C10="","",C10/ProteinGoal) | J10: =IF(D10="","",D10/CarbGoal) | K10: =IF(E10="","",E10/FatGoal) | L10: =IF(F10="","",F10/FiberGoal) | M10: =IF(G10="","",G10/WaterGoal)
A11: ='Daily Tracker'!A11 -> 46029 | G11: =IF('Daily Tracker'!I11="","",'Daily Tracker'!I11) | H11: =IF(B11="","",B11/CalorieGoal) | I11: =IF(C11="","",C11/ProteinGoal) | J11: =IF(D11="","",D11/CarbGoal) | K11: =IF(E11="","",E11/FatGoal) | L11: =IF(F11="","",F11/FiberGoal) | M11: =IF(G11="","",G11/WaterGoal)
A12: ='Daily Tracker'!A12 -> 46030 | G12: =IF('Daily Tracker'!I12="","",'Daily Tracker'!I12) | H12: =IF(B12="","",B12/CalorieGoal) | I12: =IF(C12="","",C12/ProteinGoal) | J12: =IF(D12="","",D12/CarbGoal) | K12: =IF(E12="","",E12/FatGoal) | L12: =IF(F12="","",F12/FiberGoal) | M12: =IF(G12="","",G12/WaterGoal)
A13: ='Daily Tracker'!A13 -> 46031 | G13: =IF('Daily Tracker'!I13="","",'Daily Tracker'!I13) | H13: =IF(B13="","",B13/CalorieGoal) | I13: =IF(C13="","",C13/ProteinGoal) | J13: =IF(D13="","",D13/CarbGoal) | K13: =IF(E13="","",E13/FatGoal) | L13: =IF(F13="","",F13/FiberGoal) | M13: =IF(G13="","",G13/WaterGoal)
A14: ='Daily Tracker'!A14 -> 46032 | G14: =IF('Daily Tracker'!I14="","",'Daily Tracker'!I14) | H14: =IF(B14="","",B14/CalorieGoal) | I14: =IF(C14="","",C14/ProteinGoal) | J14: =IF(D14="","",D14/CarbGoal) | K14: =IF(E14="","",E14/FatGoal) | L14: =IF(F14="","",F14/FiberGoal) | M14: =IF(G14="","",G14/WaterGoal)
A15: ='Daily Tracker'!A15 -> 46033 | G15: =IF('Daily Tracker'!I15="","",'Daily Tracker'!I15) | H15: =IF(B15="","",B15/CalorieGoal) | I15: =IF(C15="","",C15/ProteinGoal) | J15: =IF(D15="","",D15/CarbGoal) | K15: =IF(E15="","",E15/FatGoal) | L15: =IF(F15="","",F15/FiberGoal) | M15: =IF(G15="","",G15/WaterGoal)
A16: ='Daily Tracker'!A16 -> 46034 | G16: =IF('Daily Tracker'!I16="","",'Daily Tracker'!I16) | H16: =IF(B16="","",B16/CalorieGoal) | I16: =IF(C16="","",C16/ProteinGoal) | J16: =IF(D16="","",D16/CarbGoal) | K16: =IF(E16="","",E16/FatGoal) | L16: =IF(F16="","",F16/FiberGoal) | M16: =IF(G16="","",G16/WaterGoal)
A17: ='Daily Tracker'!A17 -> 46035 | G17: =IF('Daily Tracker'!I17="","",'Daily Tracker'!I17) | H17: =IF(B17="","",B17/CalorieGoal) | I17: =IF(C17="","",C17/ProteinGoal) | J17: =IF(D17="","",D17/CarbGoal) | K17: =IF(E17="","",E17/FatGoal) | L17: =IF(F17="","",F17/FiberGoal) | M17: =IF(G17="","",G17/WaterGoal)
... A369: ='Daily Tracker'!A369 -> 46387 | G369: =IF('Daily Tracker'!I369="","",'Daily Tracker'!I369) | H369: =IF(B369="","",B369/CalorieGoal) | I369: =IF(C369="","",C369/ProteinGoal) | J369: =IF(D369="","",D369/CarbGoal) | K369: =IF(E369="","",E369/FatGoal) | L369: =IF(F369="","",F369/FiberGoal) | M369: =IF(G369="","",G369/WaterGoal)

Sheet Weekly Dashboard
A1: 📊 WEEKLY DASHBOARD
A2: Automatic week-by-week rollups from every log sheet — nothing to enter here.
A4: Wk # | B4: Week Start | C4: Total Steps | D4: Avg Steps/Day | E4: Avg Sleep (hrs) | F4: Workout Sessions | G4: Total Workout Time (min) | H4: Calories Burned | I4: Water Intake (L) | J4: Avg Weight (kg) | K4: Weight Change (kg) | L4: Avg Recovery Score | M4: Training Load | N4: Month
A5: 1 | B5: =StartDate+(A5-1)*7 -> 46023 | C5: =SUMIFS('Daily Tracker'!$E$5:$E$369,'Daily Tracker'!$C$5:$C$369,A5) -> 11500 | D5: =IFERROR(AVERAGEIFS('Daily Tracker'!$E$5:$E$369,'Daily Tracker'!$C$5:$C$369,A5),"") -> 11500 | E5: =IFERROR(AVERAGEIFS('Daily Tracker'!$F$5:$F$369,'Daily Tracker'!$C$5:$C$369,A5),"") -> 7.5 | F5: =COUNTIFS('Daily Tracker'!$C$5:$C$369,A5,'Daily Tracker'!$X$5:$X$369,1) -> 1 | G5: =SUMIFS('Daily Tracker'!$M$5:$M$369,'Daily Tracker'!$C$5:$C$369,A5) -> 75 | H5: =SUMIFS('Daily Tracker'!$K$5:$K$369,'Daily Tracker'!$C$5:$C$369,A5) -> 3100 | I5: =SUMIFS('Daily Tracker'!$I$5:$I$369,'Daily Tracker'!$C$5:$C$369,A5) -> 4.2 | J5: =IFERROR(AVERAGEIFS('Daily Tracker'!$G$5:$G$369,'Daily Tracker'!$C$5:$C$369,A5),"") -> 76 | L5: =IFERROR(AVERAGEIFS('Recovery Tracker'!$E$5:$E$369,'Daily Tracker'!$C$5:$C$369,A5),"") -> 84 | M5: =SUMIFS('Workout Log'!$G$5:$G$504,'Workout Log'!$L$5:$L$504,A5) -> 6880 | N5: =IF(B5="","",TEXT(B5,"mmm")) -> Jan
A6: 2 | B6: =StartDate+(A6-1)*7 -> 46030 | C6: =SUMIFS('Daily Tracker'!$E$5:$E$369,'Daily Tracker'!$C$5:$C$369,A6) -> 0 | D6: =IFERROR(AVERAGEIFS('Daily Tracker'!$E$5:$E$369,'Daily Tracker'!$C$5:$C$369,A6),"") | E6: =IFERROR(AVERAGEIFS('Daily Tracker'!$F$5:$F$369,'Daily Tracker'!$C$5:$C$369,A6),"") | F6: =COUNTIFS('Daily Tracker'!$C$5:$C$369,A6,'Daily Tracker'!$X$5:$X$369,1) -> 0 | G6: =SUMIFS('Daily Tracker'!$M$5:$M$369,'Daily Tracker'!$C$5:$C$369,A6) -> 0 | H6: =SUMIFS('Daily Tracker'!$K$5:$K$369,'Daily Tracker'!$C$5:$C$369,A6) -> 0 | I6: =SUMIFS('Daily Tracker'!$I$5:$I$369,'Daily Tracker'!$C$5:$C$369,A6) -> 0 | J6: =IFERROR(AVERAGEIFS('Daily Tracker'!$G$5:$G$369,'Daily Tracker'!$C$5:$C$369,A6),"") | K6: =IF(OR(J6="",J5=""),"",J6-J5) | L6: =IFERROR(AVERAGEIFS('Recovery Tracker'!$E$5:$E$369,'Daily Tracker'!$C$5:$C$369,A6),"") | M6: =SUMIFS('Workout Log'!$G$5:$G$504,'Workout Log'!$L$5:$L$504,A6) -> 0 | N6: =IF(B6="","",TEXT(B6,"mmm")) -> Jan
A7: 3 | B7: =StartDate+(A7-1)*7 -> 46037 | C7: =SUMIFS('Daily Tracker'!$E$5:$E$369,'Daily Tracker'!$C$5:$C$369,A7) -> 0 | D7: =IFERROR(AVERAGEIFS('Daily Tracker'!$E$5:$E$369,'Daily Tracker'!$C$5:$C$369,A7),"") | E7: =IFERROR(AVERAGEIFS('Daily Tracker'!$F$5:$F$369,'Daily Tracker'!$C$5:$C$369,A7),"") | F7: =COUNTIFS('Daily Tracker'!$C$5:$C$369,A7,'Daily Tracker'!$X$5:$X$369,1) -> 0 | G7: =SUMIFS('Daily Tracker'!$M$5:$M$369,'Daily Tracker'!$C$5:$C$369,A7) -> 0 | H7: =SUMIFS('Daily Tracker'!$K$5:$K$369,'Daily Tracker'!$C$5:$C$369,A7) -> 0 | I7: =SUMIFS('Daily Tracker'!$I$5:$I$369,'Daily Tracker'!$C$5:$C$369,A7) -> 0 | J7: =IFERROR(AVERAGEIFS('Daily Tracker'!$G$5:$G$369,'Daily Tracker'!$C$5:$C$369,A7),"") | K7: =IF(OR(J7="",J6=""),"",J7-J6) | L7: =IFERROR(AVERAGEIFS('Recovery Tracker'!$E$5:$E$369,'Daily Tracker'!$C$5:$C$369,A7),"") | M7: =SUMIFS('Workout Log'!$G$5:$G$504,'Workout Log'!$L$5:$L$504,A7) -> 0 | N7: =IF(B7="","",TEXT(B7,"mmm")) -> Jan
